Workbook

Sheet Total
Q1: Total. 2025, Kia IR
B2: ]
B3: Retail Sales by Country_2025 | S3: (Units, %)
B4: Model / Plant | G4: Total | H4: Korea | I4: U.S.A | J4: Canada | K4: Mexico | L4: *Europe | M4: Eastern Europe | N4: Latin America | O4: Middle East | P4: Africa | Q4: Asia Pacific | R4: India | S4: China
E6: Morning / Picanto | G6: =Jan!G6+Feb!G6+Mar!G6+Apr!G6+May!G6+June!G6+July!G6+Aug!G6+Sep!G6+Oct!G6+Nov!G6+Dec!G6 -> 129251 | H6: =Jan!H6+Feb!H6+Mar!H6+Apr!H6+May!H6+June!H6+July!H6+Aug!H6+Sep!H6+Oct!H6+Nov!H6+Dec!H6 -> 16297 | I6: =Jan!I6+Feb!I6+Mar!I6+Apr!I6+May!I6+June!I6+July!I6+Aug!I6+Sep!I6+Oct!I6+Nov!I6+Dec!I6 -> 0 | J6: =Jan!J6+Feb!J6+Mar!J6+Apr!J6+May!J6+June!J6+July!J6+Aug!J6+Sep!J6+Oct!J6+Nov!J6+Dec!J6 -> 0 | K6: =Jan!K6+Feb!K6+Mar!K6+Apr!K6+May!K6+June!K6+July!K6+Aug!K6+Sep!K6+Oct!K6+Nov!K6+Dec!K6 -> 0 | L6: =Jan!L6+Feb!L6+Mar!L6+Apr!L6+May!L6+June!L6+July!L6+Aug!L6+Sep!L6+Oct!L6+Nov!L6+Dec!L6 -> 62504 | M6: =Jan!M6+Feb!M6+Mar!M6+Apr!M6+May!M6+June!M6+July!M6+Aug!M6+Sep!M6+Oct!M6+Nov!M6+Dec!M6 -> 1204 | N6: =Jan!N6+Feb!N6+Mar!N6+Apr!N6+May!N6+June!N6+July!N6+Aug!N6+Sep!N6+Oct!N6+Nov!N6+Dec!N6 -> 19073 | ... S6: =Jan!S6+Feb!S6+Mar!S6+Apr!S6+May!S6+June!S6+July!S6+Aug!S6+Sep!S6+Oct!S6+Nov!S6+Dec!S6 -> 0
E7: Pride / Rio | G7: =Jan!G7+Feb!G7+Mar!G7+Apr!G7+May!G7+June!G7+July!G7+Aug!G7+Sep!G7+Oct!G7+Nov!G7+Dec!G7 -> -4 | H7: =Jan!H7+Feb!H7+Mar!H7+Apr!H7+May!H7+June!H7+July!H7+Aug!H7+Sep!H7+Oct!H7+Nov!H7+Dec!H7 -> 0 | I7: =Jan!I7+Feb!I7+Mar!I7+Apr!I7+May!I7+June!I7+July!I7+Aug!I7+Sep!I7+Oct!I7+Nov!I7+Dec!I7 -> 0 | J7: =Jan!J7+Feb!J7+Mar!J7+Apr!J7+May!J7+June!J7+July!J7+Aug!J7+Sep!J7+Oct!J7+Nov!J7+Dec!J7 -> 0 | K7: =Jan!K7+Feb!K7+Mar!K7+Apr!K7+May!K7+June!K7+July!K7+Aug!K7+Sep!K7+Oct!K7+Nov!K7+Dec!K7 -> 0 | L7: =Jan!L7+Feb!L7+Mar!L7+Apr!L7+May!L7+June!L7+July!L7+Aug!L7+Sep!L7+Oct!L7+Nov!L7+Dec!L7 -> 0 | M7: =Jan!M7+Feb!M7+Mar!M7+Apr!M7+May!M7+June!M7+July!M7+Aug!M7+Sep!M7+Oct!M7+Nov!M7+Dec!M7 -> 0 | N7: =Jan!N7+Feb!N7+Mar!N7+Apr!N7+May!N7+June!N7+July!N7+Aug!N7+Sep!N7+Oct!N7+Nov!N7+Dec!N7 -> 0 | ... S7: =Jan!S7+Feb!S7+Mar!S7+Apr!S7+May!S7+June!S7+July!S7+Aug!S7+Sep!S7+Oct!S7+Nov!S7+Dec!S7 -> 0
E8: Ray | G8: =Jan!G8+Feb!G8+Mar!G8+Apr!G8+May!G8+June!G8+July!G8+Aug!G8+Sep!G8+Oct!G8+Nov!G8+Dec!G8 -> 39384 | H8: =Jan!H8+Feb!H8+Mar!H8+Apr!H8+May!H8+June!H8+July!H8+Aug!H8+Sep!H8+Oct!H8+Nov!H8+Dec!H8 -> 39384 | I8: =Jan!I8+Feb!I8+Mar!I8+Apr!I8+May!I8+June!I8+July!I8+Aug!I8+Sep!I8+Oct!I8+Nov!I8+Dec!I8 -> 0 | J8: =Jan!J8+Feb!J8+Mar!J8+Apr!J8+May!J8+June!J8+July!J8+Aug!J8+Sep!J8+Oct!J8+Nov!J8+Dec!J8 -> 0 | K8: =Jan!K8+Feb!K8+Mar!K8+Apr!K8+May!K8+June!K8+July!K8+Aug!K8+Sep!K8+Oct!K8+Nov!K8+Dec!K8 -> 0 | L8: =Jan!L8+Feb!L8+Mar!L8+Apr!L8+May!L8+June!L8+July!L8+Aug!L8+Sep!L8+Oct!L8+Nov!L8+Dec!L8 -> 0 | M8: =Jan!M8+Feb!M8+Mar!M8+Apr!M8+May!M8+June!M8+July!M8+Aug!M8+Sep!M8+Oct!M8+Nov!M8+Dec!M8 -> 0 | N8: =Jan!N8+Feb!N8+Mar!N8+Apr!N8+May!N8+June!N8+July!N8+Aug!N8+Sep!N8+Oct!N8+Nov!N8+Dec!N8 -> 0 | ... S8: =Jan!S8+Feb!S8+Mar!S8+Apr!S8+May!S8+June!S8+July!S8+Aug!S8+Sep!S8+Oct!S8+Nov!S8+Dec!S8 -> 0
E9: Ray EV | G9: =Jan!G9+Feb!G9+Mar!G9+Apr!G9+May!G9+June!G9+July!G9+Aug!G9+Sep!G9+Oct!G9+Nov!G9+Dec!G9 -> 9270 | H9: =Jan!H9+Feb!H9+Mar!H9+Apr!H9+May!H9+June!H9+July!H9+Aug!H9+Sep!H9+Oct!H9+Nov!H9+Dec!H9 -> 9270 | I9: =Jan!I9+Feb!I9+Mar!I9+Apr!I9+May!I9+June!I9+July!I9+Aug!I9+Sep!I9+Oct!I9+Nov!I9+Dec!I9 -> 0 | J9: =Jan!J9+Feb!J9+Mar!J9+Apr!J9+May!J9+June!J9+July!J9+Aug!J9+Sep!J9+Oct!J9+Nov!J9+Dec!J9 -> 0 | K9: =Jan!K9+Feb!K9+Mar!K9+Apr!K9+May!K9+June!K9+July!K9+Aug!K9+Sep!K9+Oct!K9+Nov!K9+Dec!K9 -> 0 | L9: =Jan!L9+Feb!L9+Mar!L9+Apr!L9+May!L9+June!L9+July!L9+Aug!L9+Sep!L9+Oct!L9+Nov!L9+Dec!L9 -> 0 | M9: =Jan!M9+Feb!M9+Mar!M9+Apr!M9+May!M9+June!M9+July!M9+Aug!M9+Sep!M9+Oct!M9+Nov!M9+Dec!M9 -> 0 | N9: =Jan!N9+Feb!N9+Mar!N9+Apr!N9+May!N9+June!N9+July!N9+Aug!N9+Sep!N9+Oct!N9+Nov!N9+Dec!N9 -> 0 | ... S9: =Jan!S9+Feb!S9+Mar!S9+Apr!S9+May!S9+June!S9+July!S9+Aug!S9+Sep!S9+Oct!S9+Nov!S9+Dec!S9 -> 0
E10: K3 | G10: =Jan!G10+Feb!G10+Mar!G10+Apr!G10+May!G10+June!G10+July!G10+Aug!G10+Sep!G10+Oct!G10+Nov!G10+Dec!G10 -> 2062 | H10: =Jan!H10+Feb!H10+Mar!H10+Apr!H10+May!H10+June!H10+July!H10+Aug!H10+Sep!H10+Oct!H10+Nov!H10+Dec!H10 -> 0 | I10: =Jan!I10+Feb!I10+Mar!I10+Apr!I10+May!I10+June!I10+July!I10+Aug!I10+Sep!I10+Oct!I10+Nov!I10+Dec!I10 -> 0 | J10: =Jan!J10+Feb!J10+Mar!J10+Apr!J10+May!J10+June!J10+July!J10+Aug!J10+Sep!J10+Oct!J10+Nov!J10+Dec!J10 -> 27 | K10: =Jan!K10+Feb!K10+Mar!K10+Apr!K10+May!K10+June!K10+July!K10+Aug!K10+Sep!K10+Oct!K10+Nov!K10+Dec!K10 -> 3 | L10: =Jan!L10+Feb!L10+Mar!L10+Apr!L10+May!L10+June!L10+July!L10+Aug!L10+Sep!L10+Oct!L10+Nov!L10+Dec!L10 -> 0 | M10: =Jan!M10+Feb!M10+Mar!M10+Apr!M10+May!M10+June!M10+July!M10+Aug!M10+Sep!M10+Oct!M10+Nov!M10+Dec!M10 -> 130 | N10: =Jan!N10+Feb!N10+Mar!N10+Apr!N10+May!N10+June!N10+July!N10+Aug!N10+Sep!N10+Oct!N10+Nov!N10+Dec!N10 -> 19 | ... S10: =Jan!S10+Feb!S10+Mar!S10+Apr!S10+May!S10+June!S10+July!S10+Aug!S10+Sep!S10+Oct!S10+Nov!S10+Dec!S10 -> 0
E11: K5 | G11: =Jan!G11+Feb!G11+Mar!G11+Apr!G11+May!G11+June!G11+July!G11+Aug!G11+Sep!G11+Oct!G11+Nov!G11+Dec!G11 -> 118845 | H11: =Jan!H11+Feb!H11+Mar!H11+Apr!H11+May!H11+June!H11+July!H11+Aug!H11+Sep!H11+Oct!H11+Nov!H11+Dec!H11 -> 36598 | I11: =Jan!I11+Feb!I11+Mar!I11+Apr!I11+May!I11+June!I11+July!I11+Aug!I11+Sep!I11+Oct!I11+Nov!I11+Dec!I11 -> 72748 | J11: =Jan!J11+Feb!J11+Mar!J11+Apr!J11+May!J11+June!J11+July!J11+Aug!J11+Sep!J11+Oct!J11+Nov!J11+Dec!J11 -> 0 | K11: =Jan!K11+Feb!K11+Mar!K11+Apr!K11+May!K11+June!K11+July!K11+Aug!K11+Sep!K11+Oct!K11+Nov!K11+Dec!K11 -> 0 | L11: =Jan!L11+Feb!L11+Mar!L11+Apr!L11+May!L11+June!L11+July!L11+Aug!L11+Sep!L11+Oct!L11+Nov!L11+Dec!L11 -> 23 | M11: =Jan!M11+Feb!M11+Mar!M11+Apr!M11+May!M11+June!M11+July!M11+Aug!M11+Sep!M11+Oct!M11+Nov!M11+Dec!M11 -> 63 | N11: =Jan!N11+Feb!N11+Mar!N11+Apr!N11+May!N11+June!N11+July!N11+Aug!N11+Sep!N11+Oct!N11+Nov!N11+Dec!N11 -> 147 | ... S11: =Jan!S11+Feb!S11+Mar!S11+Apr!S11+May!S11+June!S11+July!S11+Aug!S11+Sep!S11+Oct!S11+Nov!S11+Dec!S11 -> 0
E12: Stinger | G12: =Jan!G12+Feb!G12+Mar!G12+Apr!G12+May!G12+June!G12+July!G12+Aug!G12+Sep!G12+Oct!G12+Nov!G12+Dec!G12 -> 3 | H12: =Jan!H12+Feb!H12+Mar!H12+Apr!H12+May!H12+June!H12+July!H12+Aug!H12+Sep!H12+Oct!H12+Nov!H12+Dec!H12 -> 0 | I12: =Jan!I12+Feb!I12+Mar!I12+Apr!I12+May!I12+June!I12+July!I12+Aug!I12+Sep!I12+Oct!I12+Nov!I12+Dec!I12 -> 0 | J12: =Jan!J12+Feb!J12+Mar!J12+Apr!J12+May!J12+June!J12+July!J12+Aug!J12+Sep!J12+Oct!J12+Nov!J12+Dec!J12 -> 0 | K12: =Jan!K12+Feb!K12+Mar!K12+Apr!K12+May!K12+June!K12+July!K12+Aug!K12+Sep!K12+Oct!K12+Nov!K12+Dec!K12 -> 0 | L12: =Jan!L12+Feb!L12+Mar!L12+Apr!L12+May!L12+June!L12+July!L12+Aug!L12+Sep!L12+Oct!L12+Nov!L12+Dec!L12 -> 1 | M12: =Jan!M12+Feb!M12+Mar!M12+Apr!M12+May!M12+June!M12+July!M12+Aug!M12+Sep!M12+Oct!M12+Nov!M12+Dec!M12 -> 0 | N12: =Jan!N12+Feb!N12+Mar!N12+Apr!N12+May!N12+June!N12+July!N12+Aug!N12+Sep!N12+Oct!N12+Nov!N12+Dec!N12 -> 0 | ... S12: =Jan!S12+Feb!S12+Mar!S12+Apr!S12+May!S12+June!S12+July!S12+Aug!S12+Sep!S12+Oct!S12+Nov!S12+Dec!S12 -> 0
E13: K8 | G13: =Jan!G13+Feb!G13+Mar!G13+Apr!G13+May!G13+June!G13+July!G13+Aug!G13+Sep!G13+Oct!G13+Nov!G13+Dec!G13 -> 29141 | H13: =Jan!H13+Feb!H13+Mar!H13+Apr!H13+May!H13+June!H13+July!H13+Aug!H13+Sep!H13+Oct!H13+Nov!H13+Dec!H13 -> 28154 | I13: =Jan!I13+Feb!I13+Mar!I13+Apr!I13+May!I13+June!I13+July!I13+Aug!I13+Sep!I13+Oct!I13+Nov!I13+Dec!I13 -> 0 | J13: =Jan!J13+Feb!J13+Mar!J13+Apr!J13+May!J13+June!J13+July!J13+Aug!J13+Sep!J13+Oct!J13+Nov!J13+Dec!J13 -> 0 | K13: =Jan!K13+Feb!K13+Mar!K13+Apr!K13+May!K13+June!K13+July!K13+Aug!K13+Sep!K13+Oct!K13+Nov!K13+Dec!K13 -> 0 | L13: =Jan!L13+Feb!L13+Mar!L13+Apr!L13+May!L13+June!L13+July!L13+Aug!L13+Sep!L13+Oct!L13+Nov!L13+Dec!L13 -> 0 | M13: =Jan!M13+Feb!M13+Mar!M13+Apr!M13+May!M13+June!M13+July!M13+Aug!M13+Sep!M13+Oct!M13+Nov!M13+Dec!M13 -> 186 | N13: =Jan!N13+Feb!N13+Mar!N13+Apr!N13+May!N13+June!N13+July!N13+Aug!N13+Sep!N13+Oct!N13+Nov!N13+Dec!N13 -> 0 | ... S13: =Jan!S13+Feb!S13+Mar!S13+Apr!S13+May!S13+June!S13+July!S13+Aug!S13+Sep!S13+Oct!S13+Nov!S13+Dec!S13 -> 0
E14: K9 | G14: =Jan!G14+Feb!G14+Mar!G14+Apr!G14+May!G14+June!G14+July!G14+Aug!G14+Sep!G14+Oct!G14+Nov!G14+Dec!G14 -> 1621 | H14: =Jan!H14+Feb!H14+Mar!H14+Apr!H14+May!H14+June!H14+July!H14+Aug!H14+Sep!H14+Oct!H14+Nov!H14+Dec!H14 -> 1581 | I14: =Jan!I14+Feb!I14+Mar!I14+Apr!I14+May!I14+June!I14+July!I14+Aug!I14+Sep!I14+Oct!I14+Nov!I14+Dec!I14 -> 0 | J14: =Jan!J14+Feb!J14+Mar!J14+Apr!J14+May!J14+June!J14+July!J14+Aug!J14+Sep!J14+Oct!J14+Nov!J14+Dec!J14 -> 0 | K14: =Jan!K14+Feb!K14+Mar!K14+Apr!K14+May!K14+June!K14+July!K14+Aug!K14+Sep!K14+Oct!K14+Nov!K14+Dec!K14 -> 0 | L14: =Jan!L14+Feb!L14+Mar!L14+Apr!L14+May!L14+June!L14+July!L14+Aug!L14+Sep!L14+Oct!L14+Nov!L14+Dec!L14 -> 0 | M14: =Jan!M14+Feb!M14+Mar!M14+Apr!M14+May!M14+June!M14+July!M14+Aug!M14+Sep!M14+Oct!M14+Nov!M14+Dec!M14 -> 39 | N14: =Jan!N14+Feb!N14+Mar!N14+Apr!N14+May!N14+June!N14+July!N14+Aug!N14+Sep!N14+Oct!N14+Nov!N14+Dec!N14 -> 0 | ... S14: =Jan!S14+Feb!S14+Mar!S14+Apr!S14+May!S14+June!S14+July!S14+Aug!S14+Sep!S14+Oct!S14+Nov!S14+Dec!S14 -> 0
E15: Stonic | G15: =Jan!G15+Feb!G15+Mar!G15+Apr!G15+May!G15+June!G15+July!G15+Aug!G15+Sep!G15+Oct!G15+Nov!G15+Dec!G15 -> 74394 | H15: =Jan!H15+Feb!H15+Mar!H15+Apr!H15+May!H15+June!H15+July!H15+Aug!H15+Sep!H15+Oct!H15+Nov!H15+Dec!H15 -> 0 | I15: =Jan!I15+Feb!I15+Mar!I15+Apr!I15+May!I15+June!I15+July!I15+Aug!I15+Sep!I15+Oct!I15+Nov!I15+Dec!I15 -> 0 | J15: =Jan!J15+Feb!J15+Mar!J15+Apr!J15+May!J15+June!J15+July!J15+Aug!J15+Sep!J15+Oct!J15+Nov!J15+Dec!J15 -> 0 | K15: =Jan!K15+Feb!K15+Mar!K15+Apr!K15+May!K15+June!K15+July!K15+Aug!K15+Sep!K15+Oct!K15+Nov!K15+Dec!K15 -> 0 | L15: =Jan!L15+Feb!L15+Mar!L15+Apr!L15+May!L15+June!L15+July!L15+Aug!L15+Sep!L15+Oct!L15+Nov!L15+Dec!L15 -> 53288 | M15: =Jan!M15+Feb!M15+Mar!M15+Apr!M15+May!M15+June!M15+July!M15+Aug!M15+Sep!M15+Oct!M15+Nov!M15+Dec!M15 -> 3481 | N15: =Jan!N15+Feb!N15+Mar!N15+Apr!N15+May!N15+June!N15+July!N15+Aug!N15+Sep!N15+Oct!N15+Nov!N15+Dec!N15 -> 2290 | ... S15: =Jan!S15+Feb!S15+Mar!S15+Apr!S15+May!S15+June!S15+July!S15+Aug!S15+Sep!S15+Oct!S15+Nov!S15+Dec!S15 -> 0
E16: Seltos | G16: =Jan!G16+Feb!G16+Mar!G16+Apr!G16+May!G16+June!G16+July!G16+Aug!G16+Sep!G16+Oct!G16+Nov!G16+Dec!G16 -> 156797 | H16: =Jan!H16+Feb!H16+Mar!H16+Apr!H16+May!H16+June!H16+July!H16+Aug!H16+Sep!H16+Oct!H16+Nov!H16+Dec!H16 -> 55917 | I16: =Jan!I16+Feb!I16+Mar!I16+Apr!I16+May!I16+June!I16+July!I16+Aug!I16+Sep!I16+Oct!I16+Nov!I16+Dec!I16 -> 56798 | J16: =Jan!J16+Feb!J16+Mar!J16+Apr!J16+May!J16+June!J16+July!J16+Aug!J16+Sep!J16+Oct!J16+Nov!J16+Dec!J16 -> 21276 | K16: =Jan!K16+Feb!K16+Mar!K16+Apr!K16+May!K16+June!K16+July!K16+Aug!K16+Sep!K16+Oct!K16+Nov!K16+Dec!K16 -> 0 | L16: =Jan!L16+Feb!L16+Mar!L16+Apr!L16+May!L16+June!L16+July!L16+Aug!L16+Sep!L16+Oct!L16+Nov!L16+Dec!L16 -> 0 | M16: =Jan!M16+Feb!M16+Mar!M16+Apr!M16+May!M16+June!M16+July!M16+Aug!M16+Sep!M16+Oct!M16+Nov!M16+Dec!M16 -> 1620 | N16: =Jan!N16+Feb!N16+Mar!N16+Apr!N16+May!N16+June!N16+July!N16+Aug!N16+Sep!N16+Oct!N16+Nov!N16+Dec!N16 -> 6044 | ... S16: =Jan!S16+Feb!S16+Mar!S16+Apr!S16+May!S16+June!S16+July!S16+Aug!S16+Sep!S16+Oct!S16+Nov!S16+Dec!S16 -> 0
E17: Soul | G17: =Jan!G17+Feb!G17+Mar!G17+Apr!G17+May!G17+June!G17+July!G17+Aug!G17+Sep!G17+Oct!G17+Nov!G17+Dec!G17 -> 54183 | H17: =Jan!H17+Feb!H17+Mar!H17+Apr!H17+May!H17+June!H17+July!H17+Aug!H17+Sep!H17+Oct!H17+Nov!H17+Dec!H17 -> 0 | I17: =Jan!I17+Feb!I17+Mar!I17+Apr!I17+May!I17+June!I17+July!I17+Aug!I17+Sep!I17+Oct!I17+Nov!I17+Dec!I17 -> 50133 | J17: =Jan!J17+Feb!J17+Mar!J17+Apr!J17+May!J17+June!J17+July!J17+Aug!J17+Sep!J17+Oct!J17+Nov!J17+Dec!J17 -> 704 | K17: =Jan!K17+Feb!K17+Mar!K17+Apr!K17+May!K17+June!K17+July!K17+Aug!K17+Sep!K17+Oct!K17+Nov!K17+Dec!K17 -> 28 | L17: =Jan!L17+Feb!L17+Mar!L17+Apr!L17+May!L17+June!L17+July!L17+Aug!L17+Sep!L17+Oct!L17+Nov!L17+Dec!L17 -> 0 | M17: =Jan!M17+Feb!M17+Mar!M17+Apr!M17+May!M17+June!M17+July!M17+Aug!M17+Sep!M17+Oct!M17+Nov!M17+Dec!M17 -> 367 | N17: =Jan!N17+Feb!N17+Mar!N17+Apr!N17+May!N17+June!N17+July!N17+Aug!N17+Sep!N17+Oct!N17+Nov!N17+Dec!N17 -> 2886 | ... S17: =Jan!S17+Feb!S17+Mar!S17+Apr!S17+May!S17+June!S17+July!S17+Aug!S17+Sep!S17+Oct!S17+Nov!S17+Dec!S17 -> 0
... E36: PV5 | G36: =Jan!G36+Feb!G36+Mar!G36+Apr!G36+May!G36+June!G36+July!G36+Aug!G36+Sep!G36+Oct!G36+Nov!G36+Dec!G36 -> 5272 | H36: =Jan!H36+Feb!H36+Mar!H36+Apr!H36+May!H36+June!H36+July!H36+Aug!H36+Sep!H36+Oct!H36+Nov!H36+Dec!H36 -> 3836 | I36: =Jan!I36+Feb!I36+Mar!I36+Apr!I36+May!I36+June!I36+July!I36+Aug!I36+Sep!I36+Oct!I36+Nov!I36+Dec!I36 -> 0 | J36: =Jan!J36+Feb!J36+Mar!J36+Apr!J36+May!J36+June!J36+July!J36+Aug!J36+Sep!J36+Oct!J36+Nov!J36+Dec!J36 -> 0 | K36: =Jan!K36+Feb!K36+Mar!K36+Apr!K36+May!K36+June!K36+July!K36+Aug!K36+Sep!K36+Oct!K36+Nov!K36+Dec!K36 -> 0 | L36: =Jan!L36+Feb!L36+Mar!L36+Apr!L36+May!L36+June!L36+July!L36+Aug!L36+Sep!L36+Oct!L36+Nov!L36+Dec!L36 -> 1430 | M36: =Jan!M36+Feb!M36+Mar!M36+Apr!M36+May!M36+June!M36+July!M36+Aug!M36+Sep!M36+Oct!M36+Nov!M36+Dec!M36 -> 0 | N36: =Jan!N36+Feb!N36+Mar!N36+Apr!N36+May!N36+June!N36+July!N36+Aug!N36+Sep!N36+Oct!N36+Nov!N36+Dec!N36 -> 0 | ... S36: =Jan!S36+Feb!S36+Mar!S36+Apr!S36+May!S36+June!S36+July!S36+Aug!S36+Sep!S36+Oct!S36+Nov!S36+Dec!S36 -> 0
B37: Korea Plants | G37: =Jan!G37+Feb!G37+Mar!G37+Apr!G37+May!G37+June!G37+July!G37+Aug!G37+Sep!G37+Oct!G37+Nov!G37+Dec!G37 -> 1550658 | H37: =Jan!H37+Feb!H37+Mar!H37+Apr!H37+May!H37+June!H37+July!H37+Aug!H37+Sep!H37+Oct!H37+Nov!H37+Dec!H37 -> 545776 | I37: =Jan!I37+Feb!I37+Mar!I37+Apr!I37+May!I37+June!I37+July!I37+Aug!I37+Sep!I37+Oct!I37+Nov!I37+Dec!I37 -> 380863 | J37: =Jan!J37+Feb!J37+Mar!J37+Apr!J37+May!J37+June!J37+July!J37+Aug!J37+Sep!J37+Oct!J37+Nov!J37+Dec!J37 -> 70513 | K37: =Jan!K37+Feb!K37+Mar!K37+Apr!K37+May!K37+June!K37+July!K37+Aug!K37+Sep!K37+Oct!K37+Nov!K37+Dec!K37 -> 8154 | L37: =Jan!L37+Feb!L37+Mar!L37+Apr!L37+May!L37+June!L37+July!L37+Aug!L37+Sep!L37+Oct!L37+Nov!L37+Dec!L37 -> 268687 | M37: =Jan!M37+Feb!M37+Mar!M37+Apr!M37+May!M37+June!M37+July!M37+Aug!M37+Sep!M37+Oct!M37+Nov!M37+Dec!M37 -> 25334 | N37: =Jan!N37+Feb!N37+Mar!N37+Apr!N37+May!N37+June!N37+July!N37+Aug!N37+Sep!N37+Oct!N37+Nov!N37+Dec!N37 -> 59090 | ... S37: =Jan!S37+Feb!S37+Mar!S37+Apr!S37+May!S37+June!S37+July!S37+Aug!S37+Sep!S37+Oct!S37+Nov!S37+Dec!S37 -> 23
E38: Optima / K5 | G38: =Jan!G38+Feb!G38+Mar!G38+Apr!G38+May!G38+June!G38+July!G38+Aug!G38+Sep!G38+Oct!G38+Nov!G38+Dec!G38 -> 4 | H38: =Jan!H38+Feb!H38+Mar!H38+Apr!H38+May!H38+June!H38+July!H38+Aug!H38+Sep!H38+Oct!H38+Nov!H38+Dec!H38 -> 0 | I38: =Jan!I38+Feb!I38+Mar!I38+Apr!I38+May!I38+June!I38+July!I38+Aug!I38+Sep!I38+Oct!I38+Nov!I38+Dec!I38 -> 3 | J38: =Jan!J38+Feb!J38+Mar!J38+Apr!J38+May!J38+June!J38+July!J38+Aug!J38+Sep!J38+Oct!J38+Nov!J38+Dec!J38 -> 1 | K38: =Jan!K38+Feb!K38+Mar!K38+Apr!K38+May!K38+June!K38+July!K38+Aug!K38+Sep!K38+Oct!K38+Nov!K38+Dec!K38 -> 0 | L38: =Jan!L38+Feb!L38+Mar!L38+Apr!L38+May!L38+June!L38+July!L38+Aug!L38+Sep!L38+Oct!L38+Nov!L38+Dec!L38 -> 0 | M38: =Jan!M38+Feb!M38+Mar!M38+Apr!M38+May!M38+June!M38+July!M38+Aug!M38+Sep!M38+Oct!M38+Nov!M38+Dec!M38 -> 0 | N38: =Jan!N38+Feb!N38+Mar!N38+Apr!N38+May!N38+June!N38+July!N38+Aug!N38+Sep!N38+Oct!N38+Nov!N38+Dec!N38 -> 0 | ... S38: =Jan!S38+Feb!S38+Mar!S38+Apr!S38+May!S38+June!S38+July!S38+Aug!S38+Sep!S38+Oct!S38+Nov!S38+Dec!S38 -> 0
E39: Sportage | G39: =Jan!G39+Feb!G39+Mar!G39+Apr!G39+May!G39+June!G39+July!G39+Aug!G39+Sep!G39+Oct!G39+Nov!G39+Dec!G39 -> 112310 | H39: =Jan!H39+Feb!H39+Mar!H39+Apr!H39+May!H39+June!H39+July!H39+Aug!H39+Sep!H39+Oct!H39+Nov!H39+Dec!H39 -> 0 | I39: =Jan!I39+Feb!I39+Mar!I39+Apr!I39+May!I39+June!I39+July!I39+Aug!I39+Sep!I39+Oct!I39+Nov!I39+Dec!I39 -> 111311 | J39: =Jan!J39+Feb!J39+Mar!J39+Apr!J39+May!J39+June!J39+July!J39+Aug!J39+Sep!J39+Oct!J39+Nov!J39+Dec!J39 -> 0 | K39: =Jan!K39+Feb!K39+Mar!K39+Apr!K39+May!K39+June!K39+July!K39+Aug!K39+Sep!K39+Oct!K39+Nov!K39+Dec!K39 -> 0 | L39: =Jan!L39+Feb!L39+Mar!L39+Apr!L39+May!L39+June!L39+July!L39+Aug!L39+Sep!L39+Oct!L39+Nov!L39+Dec!L39 -> 0 | M39: =Jan!M39+Feb!M39+Mar!M39+Apr!M39+May!M39+June!M39+July!M39+Aug!M39+Sep!M39+Oct!M39+Nov!M39+Dec!M39 -> 0 | N39: =Jan!N39+Feb!N39+Mar!N39+Apr!N39+May!N39+June!N39+July!N39+Aug!N39+Sep!N39+Oct!N39+Nov!N39+Dec!N39 -> 999 | ... S39: =Jan!S39+Feb!S39+Mar!S39+Apr!S39+May!S39+June!S39+July!S39+Aug!S39+Sep!S39+Oct!S39+Nov!S39+Dec!S39 -> 0
E40: Sorento | G40: =Jan!G40+Feb!G40+Mar!G40+Apr!G40+May!G40+June!G40+July!G40+Aug!G40+Sep!G40+Oct!G40+Nov!G40+Dec!G40 -> 83802 | H40: =Jan!H40+Feb!H40+Mar!H40+Apr!H40+May!H40+June!H40+July!H40+Aug!H40+Sep!H40+Oct!H40+Nov!H40+Dec!H40 -> 0 | I40: =Jan!I40+Feb!I40+Mar!I40+Apr!I40+May!I40+June!I40+July!I40+Aug!I40+Sep!I40+Oct!I40+Nov!I40+Dec!I40 -> 74284 | J40: =Jan!J40+Feb!J40+Mar!J40+Apr!J40+May!J40+June!J40+July!J40+Aug!J40+Sep!J40+Oct!J40+Nov!J40+Dec!J40 -> 7114 | K40: =Jan!K40+Feb!K40+Mar!K40+Apr!K40+May!K40+June!K40+July!K40+Aug!K40+Sep!K40+Oct!K40+Nov!K40+Dec!K40 -> 1731 | L40: =Jan!L40+Feb!L40+Mar!L40+Apr!L40+May!L40+June!L40+July!L40+Aug!L40+Sep!L40+Oct!L40+Nov!L40+Dec!L40 -> 0 | M40: =Jan!M40+Feb!M40+Mar!M40+Apr!M40+May!M40+June!M40+July!M40+Aug!M40+Sep!M40+Oct!M40+Nov!M40+Dec!M40 -> 0 | N40: =Jan!N40+Feb!N40+Mar!N40+Apr!N40+May!N40+June!N40+July!N40+Aug!N40+Sep!N40+Oct!N40+Nov!N40+Dec!N40 -> 662 | ... S40: =Jan!S40+Feb!S40+Mar!S40+Apr!S40+May!S40+June!S40+July!S40+Aug!S40+Sep!S40+Oct!S40+Nov!S40+Dec!S40 -> 0
E41: Telluride | G41: =Jan!G41+Feb!G41+Mar!G41+Apr!G41+May!G41+June!G41+July!G41+Aug!G41+Sep!G41+Oct!G41+Nov!G41+Dec!G41 -> 126784 | H41: =Jan!H41+Feb!H41+Mar!H41+Apr!H41+May!H41+June!H41+July!H41+Aug!H41+Sep!H41+Oct!H41+Nov!H41+Dec!H41 -> 0 | I41: =Jan!I41+Feb!I41+Mar!I41+Apr!I41+May!I41+June!I41+July!I41+Aug!I41+Sep!I41+Oct!I41+Nov!I41+Dec!I41 -> 123281 | J41: =Jan!J41+Feb!J41+Mar!J41+Apr!J41+May!J41+June!J41+July!J41+Aug!J41+Sep!J41+Oct!J41+Nov!J41+Dec!J41 -> 2170 | K41: =Jan!K41+Feb!K41+Mar!K41+Apr!K41+May!K41+June!K41+July!K41+Aug!K41+Sep!K41+Oct!K41+Nov!K41+Dec!K41 -> 371 | L41: =Jan!L41+Feb!L41+Mar!L41+Apr!L41+May!L41+June!L41+July!L41+Aug!L41+Sep!L41+Oct!L41+Nov!L41+Dec!L41 -> 0 | M41: =Jan!M41+Feb!M41+Mar!M41+Apr!M41+May!M41+June!M41+July!M41+Aug!M41+Sep!M41+Oct!M41+Nov!M41+Dec!M41 -> 0 | N41: =Jan!N41+Feb!N41+Mar!N41+Apr!N41+May!N41+June!N41+July!N41+Aug!N41+Sep!N41+Oct!N41+Nov!N41+Dec!N41 -> 196 | ... S41: =Jan!S41+Feb!S41+Mar!S41+Apr!S41+May!S41+June!S41+July!S41+Aug!S41+Sep!S41+Oct!S41+Nov!S41+Dec!S41 -> 0
E42: EV6 | G42: =Jan!G42+Feb!G42+Mar!G42+Apr!G42+May!G42+June!G42+July!G42+Aug!G42+Sep!G42+Oct!G42+Nov!G42+Dec!G42 -> 9460 | H42: =Jan!H42+Feb!H42+Mar!H42+Apr!H42+May!H42+June!H42+July!H42+Aug!H42+Sep!H42+Oct!H42+Nov!H42+Dec!H42 -> 0 | I42: =Jan!I42+Feb!I42+Mar!I42+Apr!I42+May!I42+June!I42+July!I42+Aug!I42+Sep!I42+Oct!I42+Nov!I42+Dec!I42 -> 8651 | J42: =Jan!J42+Feb!J42+Mar!J42+Apr!J42+May!J42+June!J42+July!J42+Aug!J42+Sep!J42+Oct!J42+Nov!J42+Dec!J42 -> 809 | K42: =Jan!K42+Feb!K42+Mar!K42+Apr!K42+May!K42+June!K42+July!K42+Aug!K42+Sep!K42+Oct!K42+Nov!K42+Dec!K42 -> 0 | L42: =Jan!L42+Feb!L42+Mar!L42+Apr!L42+May!L42+June!L42+July!L42+Aug!L42+Sep!L42+Oct!L42+Nov!L42+Dec!L42 -> 0 | M42: =Jan!M42+Feb!M42+Mar!M42+Apr!M42+May!M42+June!M42+July!M42+Aug!M42+Sep!M42+Oct!M42+Nov!M42+Dec!M42 -> 0 | N42: =Jan!N42+Feb!N42+Mar!N42+Apr!N42+May!N42+June!N42+July!N42+Aug!N42+Sep!N42+Oct!N42+Nov!N42+Dec!N42 -> 0 | ... S42: =Jan!S42+Feb!S42+Mar!S42+Apr!S42+May!S42+June!S42+July!S42+Aug!S42+Sep!S42+Oct!S42+Nov!S42+Dec!S42 -> 0
E43: EV9 | G43: =Jan!G43+Feb!G43+Mar!G43+Apr!G43+May!G43+June!G43+July!G43+Aug!G43+Sep!G43+Oct!G43+Nov!G43+Dec!G43 -> 13263 | H43: =Jan!H43+Feb!H43+Mar!H43+Apr!H43+May!H43+June!H43+July!H43+Aug!H43+Sep!H43+Oct!H43+Nov!H43+Dec!H43 -> 0 | I43: =Jan!I43+Feb!I43+Mar!I43+Apr!I43+May!I43+June!I43+July!I43+Aug!I43+Sep!I43+Oct!I43+Nov!I43+Dec!I43 -> 13248 | J43: =Jan!J43+Feb!J43+Mar!J43+Apr!J43+May!J43+June!J43+July!J43+Aug!J43+Sep!J43+Oct!J43+Nov!J43+Dec!J43 -> 0 | K43: =Jan!K43+Feb!K43+Mar!K43+Apr!K43+May!K43+June!K43+July!K43+Aug!K43+Sep!K43+Oct!K43+Nov!K43+Dec!K43 -> 0 | L43: =Jan!L43+Feb!L43+Mar!L43+Apr!L43+May!L43+June!L43+July!L43+Aug!L43+Sep!L43+Oct!L43+Nov!L43+Dec!L43 -> 0 | M43: =Jan!M43+Feb!M43+Mar!M43+Apr!M43+May!M43+June!M43+July!M43+Aug!M43+Sep!M43+Oct!M43+Nov!M43+Dec!M43 -> 0 | N43: =Jan!N43+Feb!N43+Mar!N43+Apr!N43+May!N43+June!N43+July!N43+Aug!N43+Sep!N43+Oct!N43+Nov!N43+Dec!N43 -> 14 | ... S43: =Jan!S43+Feb!S43+Mar!S43+Apr!S43+May!S43+June!S43+July!S43+Aug!S43+Sep!S43+Oct!S43+Nov!S43+Dec!S43 -> 0
B44: U.S. Plant | G44: =Jan!G44+Feb!G44+Mar!G44+Apr!G44+May!G44+June!G44+July!G44+Aug!G44+Sep!G44+Oct!G44+Nov!G44+Dec!G44 -> 345623 | H44: =Jan!H44+Feb!H44+Mar!H44+Apr!H44+May!H44+June!H44+July!H44+Aug!H44+Sep!H44+Oct!H44+Nov!H44+Dec!H44 -> 0 | I44: =Jan!I44+Feb!I44+Mar!I44+Apr!I44+May!I44+June!I44+July!I44+Aug!I44+Sep!I44+Oct!I44+Nov!I44+Dec!I44 -> 330778 | J44: =Jan!J44+Feb!J44+Mar!J44+Apr!J44+May!J44+June!J44+July!J44+Aug!J44+Sep!J44+Oct!J44+Nov!J44+Dec!J44 -> 10094 | K44: =Jan!K44+Feb!K44+Mar!K44+Apr!K44+May!K44+June!K44+July!K44+Aug!K44+Sep!K44+Oct!K44+Nov!K44+Dec!K44 -> 2102 | L44: =Jan!L44+Feb!L44+Mar!L44+Apr!L44+May!L44+June!L44+July!L44+Aug!L44+Sep!L44+Oct!L44+Nov!L44+Dec!L44 -> 0 | M44: =Jan!M44+Feb!M44+Mar!M44+Apr!M44+May!M44+June!M44+July!M44+Aug!M44+Sep!M44+Oct!M44+Nov!M44+Dec!M44 -> 0 | N44: =Jan!N44+Feb!N44+Mar!N44+Apr!N44+May!N44+June!N44+July!N44+Aug!N44+Sep!N44+Oct!N44+Nov!N44+Dec!N44 -> 1871 | ... S44: =Jan!S44+Feb!S44+Mar!S44+Apr!S44+May!S44+June!S44+July!S44+Aug!S44+Sep!S44+Oct!S44+Nov!S44+Dec!S44 -> 0
E45: EV2 | G45: =Jan!G45+Feb!G45+Mar!G45+Apr!G45+May!G45+June!G45+July!G45+Aug!G45+Sep!G45+Oct!G45+Nov!G45+Dec!G45 -> 0 | H45: =Jan!H45+Feb!H45+Mar!H45+Apr!H45+May!H45+June!H45+July!H45+Aug!H45+Sep!H45+Oct!H45+Nov!H45+Dec!H45 -> 0 | I45: =Jan!I45+Feb!I45+Mar!I45+Apr!I45+May!I45+June!I45+July!I45+Aug!I45+Sep!I45+Oct!I45+Nov!I45+Dec!I45 -> 0 | J45: =Jan!J45+Feb!J45+Mar!J45+Apr!J45+May!J45+June!J45+July!J45+Aug!J45+Sep!J45+Oct!J45+Nov!J45+Dec!J45 -> 0 | K45: =Jan!K45+Feb!K45+Mar!K45+Apr!K45+May!K45+June!K45+July!K45+Aug!K45+Sep!K45+Oct!K45+Nov!K45+Dec!K45 -> 0 | L45: =Jan!L45+Feb!L45+Mar!L45+Apr!L45+May!L45+June!L45+July!L45+Aug!L45+Sep!L45+Oct!L45+Nov!L45+Dec!L45 -> 0 | M45: =Jan!M45+Feb!M45+Mar!M45+Apr!M45+May!M45+June!M45+July!M45+Aug!M45+Sep!M45+Oct!M45+Nov!M45+Dec!M45 -> 0 | N45: =Jan!N45+Feb!N45+Mar!N45+Apr!N45+May!N45+June!N45+July!N45+Aug!N45+Sep!N45+Oct!N45+Nov!N45+Dec!N45 -> 0 | ... S45: =Jan!S45+Feb!S45+Mar!S45+Apr!S45+May!S45+June!S45+July!S45+Aug!S45+Sep!S45+Oct!S45+Nov!S45+Dec!S45 -> 0
E46: EV4 | G46: =Jan!G46+Feb!G46+Mar!G46+Apr!G46+May!G46+June!G46+July!G46+Aug!G46+Sep!G46+Oct!G46+Nov!G46+Dec!G46 -> 3936 | H46: =Jan!H46+Feb!H46+Mar!H46+Apr!H46+May!H46+June!H46+July!H46+Aug!H46+Sep!H46+Oct!H46+Nov!H46+Dec!H46 -> 0 | I46: =Jan!I46+Feb!I46+Mar!I46+Apr!I46+May!I46+June!I46+July!I46+Aug!I46+Sep!I46+Oct!I46+Nov!I46+Dec!I46 -> 0 | J46: =Jan!J46+Feb!J46+Mar!J46+Apr!J46+May!J46+June!J46+July!J46+Aug!J46+Sep!J46+Oct!J46+Nov!J46+Dec!J46 -> 0 | K46: =Jan!K46+Feb!K46+Mar!K46+Apr!K46+May!K46+June!K46+July!K46+Aug!K46+Sep!K46+Oct!K46+Nov!K46+Dec!K46 -> 0 | L46: =Jan!L46+Feb!L46+Mar!L46+Apr!L46+May!L46+June!L46+July!L46+Aug!L46+Sep!L46+Oct!L46+Nov!L46+Dec!L46 -> 3936 | M46: =Jan!M46+Feb!M46+Mar!M46+Apr!M46+May!M46+June!M46+July!M46+Aug!M46+Sep!M46+Oct!M46+Nov!M46+Dec!M46 -> 0 | N46: =Jan!N46+Feb!N46+Mar!N46+Apr!N46+May!N46+June!N46+July!N46+Aug!N46+Sep!N46+Oct!N46+Nov!N46+Dec!N46 -> 0 | ... S46: =Jan!S46+Feb!S46+Mar!S46+Apr!S46+May!S46+June!S46+July!S46+Aug!S46+Sep!S46+Oct!S46+Nov!S46+Dec!S46 -> 0
E47: Cee'd | G47: =Jan!G47+Feb!G47+Mar!G47+Apr!G47+May!G47+June!G47+July!G47+Aug!G47+Sep!G47+Oct!G47+Nov!G47+Dec!G47 -> 65131 | H47: =Jan!H47+Feb!H47+Mar!H47+Apr!H47+May!H47+June!H47+July!H47+Aug!H47+Sep!H47+Oct!H47+Nov!H47+Dec!H47 -> 0 | I47: =Jan!I47+Feb!I47+Mar!I47+Apr!I47+May!I47+June!I47+July!I47+Aug!I47+Sep!I47+Oct!I47+Nov!I47+Dec!I47 -> 0 | J47: =Jan!J47+Feb!J47+Mar!J47+Apr!J47+May!J47+June!J47+July!J47+Aug!J47+Sep!J47+Oct!J47+Nov!J47+Dec!J47 -> 0 | K47: =Jan!K47+Feb!K47+Mar!K47+Apr!K47+May!K47+June!K47+July!K47+Aug!K47+Sep!K47+Oct!K47+Nov!K47+Dec!K47 -> 0 | L47: =Jan!L47+Feb!L47+Mar!L47+Apr!L47+May!L47+June!L47+July!L47+Aug!L47+Sep!L47+Oct!L47+Nov!L47+Dec!L47 -> 61424 | M47: =Jan!M47+Feb!M47+Mar!M47+Apr!M47+May!M47+June!M47+July!M47+Aug!M47+Sep!M47+Oct!M47+Nov!M47+Dec!M47 -> 3303 | N47: =Jan!N47+Feb!N47+Mar!N47+Apr!N47+May!N47+June!N47+July!N47+Aug!N47+Sep!N47+Oct!N47+Nov!N47+Dec!N47 -> 29 | ... S47: =Jan!S47+Feb!S47+Mar!S47+Apr!S47+May!S47+June!S47+July!S47+Aug!S47+Sep!S47+Oct!S47+Nov!S47+Dec!S47 -> 0
E48: Cee'd CUV | G48: =Jan!G48+Feb!G48+Mar!G48+Apr!G48+May!G48+June!G48+July!G48+Aug!G48+Sep!G48+Oct!G48+Nov!G48+Dec!G48 -> 27470 | H48: =Jan!H48+Feb!H48+Mar!H48+Apr!H48+May!H48+June!H48+July!H48+Aug!H48+Sep!H48+Oct!H48+Nov!H48+Dec!H48 -> 0 | I48: =Jan!I48+Feb!I48+Mar!I48+Apr!I48+May!I48+June!I48+July!I48+Aug!I48+Sep!I48+Oct!I48+Nov!I48+Dec!I48 -> 0 | J48: =Jan!J48+Feb!J48+Mar!J48+Apr!J48+May!J48+June!J48+July!J48+Aug!J48+Sep!J48+Oct!J48+Nov!J48+Dec!J48 -> 0 | K48: =Jan!K48+Feb!K48+Mar!K48+Apr!K48+May!K48+June!K48+July!K48+Aug!K48+Sep!K48+Oct!K48+Nov!K48+Dec!K48 -> 0 | L48: =Jan!L48+Feb!L48+Mar!L48+Apr!L48+May!L48+June!L48+July!L48+Aug!L48+Sep!L48+Oct!L48+Nov!L48+Dec!L48 -> 23326 | M48: =Jan!M48+Feb!M48+Mar!M48+Apr!M48+May!M48+June!M48+July!M48+Aug!M48+Sep!M48+Oct!M48+Nov!M48+Dec!M48 -> 2959 | N48: =Jan!N48+Feb!N48+Mar!N48+Apr!N48+May!N48+June!N48+July!N48+Aug!N48+Sep!N48+Oct!N48+Nov!N48+Dec!N48 -> 125 | ... S48: =Jan!S48+Feb!S48+Mar!S48+Apr!S48+May!S48+June!S48+July!S48+Aug!S48+Sep!S48+Oct!S48+Nov!S48+Dec!S48 -> 0
E49: Sportage | G49: =Jan!G49+Feb!G49+Mar!G49+Apr!G49+May!G49+June!G49+July!G49+Aug!G49+Sep!G49+Oct!G49+Nov!G49+Dec!G49 -> 190111 | H49: =Jan!H49+Feb!H49+Mar!H49+Apr!H49+May!H49+June!H49+July!H49+Aug!H49+Sep!H49+Oct!H49+Nov!H49+Dec!H49 -> 0 | I49: =Jan!I49+Feb!I49+Mar!I49+Apr!I49+May!I49+June!I49+July!I49+Aug!I49+Sep!I49+Oct!I49+Nov!I49+Dec!I49 -> 0 | J49: =Jan!J49+Feb!J49+Mar!J49+Apr!J49+May!J49+June!J49+July!J49+Aug!J49+Sep!J49+Oct!J49+Nov!J49+Dec!J49 -> 0 | K49: =Jan!K49+Feb!K49+Mar!K49+Apr!K49+May!K49+June!K49+July!K49+Aug!K49+Sep!K49+Oct!K49+Nov!K49+Dec!K49 -> 0 | L49: =Jan!L49+Feb!L49+Mar!L49+Apr!L49+May!L49+June!L49+July!L49+Aug!L49+Sep!L49+Oct!L49+Nov!L49+Dec!L49 -> 149677 | M49: =Jan!M49+Feb!M49+Mar!M49+Apr!M49+May!M49+June!M49+July!M49+Aug!M49+Sep!M49+Oct!M49+Nov!M49+Dec!M49 -> 10762 | N49: =Jan!N49+Feb!N49+Mar!N49+Apr!N49+May!N49+June!N49+July!N49+Aug!N49+Sep!N49+Oct!N49+Nov!N49+Dec!N49 -> 3647 | ... S49: =Jan!S49+Feb!S49+Mar!S49+Apr!S49+May!S49+June!S49+July!S49+Aug!S49+Sep!S49+Oct!S49+Nov!S49+Dec!S49 -> 0
B50: Slovakia Plant | G50: =Jan!G50+Feb!G50+Mar!G50+Apr!G50+May!G50+June!G50+July!G50+Aug!G50+Sep!G50+Oct!G50+Nov!G50+Dec!G50 -> 286648 | H50: =Jan!H50+Feb!H50+Mar!H50+Apr!H50+May!H50+June!H50+July!H50+Aug!H50+Sep!H50+Oct!H50+Nov!H50+Dec!H50 -> 0 | I50: =Jan!I50+Feb!I50+Mar!I50+Apr!I50+May!I50+June!I50+July!I50+Aug!I50+Sep!I50+Oct!I50+Nov!I50+Dec!I50 -> 0 | J50: =Jan!J50+Feb!J50+Mar!J50+Apr!J50+May!J50+June!J50+July!J50+Aug!J50+Sep!J50+Oct!J50+Nov!J50+Dec!J50 -> 0 | K50: =Jan!K50+Feb!K50+Mar!K50+Apr!K50+May!K50+June!K50+July!K50+Aug!K50+Sep!K50+Oct!K50+Nov!K50+Dec!K50 -> 0 | L50: =Jan!L50+Feb!L50+Mar!L50+Apr!L50+May!L50+June!L50+July!L50+Aug!L50+Sep!L50+Oct!L50+Nov!L50+Dec!L50 -> 238363 | M50: =Jan!M50+Feb!M50+Mar!M50+Apr!M50+May!M50+June!M50+July!M50+Aug!M50+Sep!M50+Oct!M50+Nov!M50+Dec!M50 -> 17024 | N50: =Jan!N50+Feb!N50+Mar!N50+Apr!N50+May!N50+June!N50+July!N50+Aug!N50+Sep!N50+Oct!N50+Nov!N50+Dec!N50 -> 3801 | ... S50: =Jan!S50+Feb!S50+Mar!S50+Apr!S50+May!S50+June!S50+July!S50+Aug!S50+Sep!S50+Oct!S50+Nov!S50+Dec!S50 -> 0
E51: Rio (Pride) | G51: =Jan!G51+Feb!G51+Mar!G51+Apr!G51+May!G51+June!G51+July!G51+Aug!G51+Sep!G51+Oct!G51+Nov!G51+Dec!G51 -> 7 | H51: =Jan!H51+Feb!H51+Mar!H51+Apr!H51+May!H51+June!H51+July!H51+Aug!H51+Sep!H51+Oct!H51+Nov!H51+Dec!H51 -> 0 | I51: =Jan!I51+Feb!I51+Mar!I51+Apr!I51+May!I51+June!I51+July!I51+Aug!I51+Sep!I51+Oct!I51+Nov!I51+Dec!I51 -> 0 | J51: =Jan!J51+Feb!J51+Mar!J51+Apr!J51+May!J51+June!J51+July!J51+Aug!J51+Sep!J51+Oct!J51+Nov!J51+Dec!J51 -> 3 | K51: =Jan!K51+Feb!K51+Mar!K51+Apr!K51+May!K51+June!K51+July!K51+Aug!K51+Sep!K51+Oct!K51+Nov!K51+Dec!K51 -> 0 | L51: =Jan!L51+Feb!L51+Mar!L51+Apr!L51+May!L51+June!L51+July!L51+Aug!L51+Sep!L51+Oct!L51+Nov!L51+Dec!L51 -> 0 | M51: =Jan!M51+Feb!M51+Mar!M51+Apr!M51+May!M51+June!M51+July!M51+Aug!M51+Sep!M51+Oct!M51+Nov!M51+Dec!M51 -> 0 | N51: =Jan!N51+Feb!N51+Mar!N51+Apr!N51+May!N51+June!N51+July!N51+Aug!N51+Sep!N51+Oct!N51+Nov!N51+Dec!N51 -> 2 | ... S51: =Jan!S51+Feb!S51+Mar!S51+Apr!S51+May!S51+June!S51+July!S51+Aug!S51+Sep!S51+Oct!S51+Nov!S51+Dec!S51 -> 0
E52: K3 | G52: =Jan!G52+Feb!G52+Mar!G52+Apr!G52+May!G52+June!G52+July!G52+Aug!G52+Sep!G52+Oct!G52+Nov!G52+Dec!G52 -> 81457 | H52: =Jan!H52+Feb!H52+Mar!H52+Apr!H52+May!H52+June!H52+July!H52+Aug!H52+Sep!H52+Oct!H52+Nov!H52+Dec!H52 -> 0 | I52: =Jan!I52+Feb!I52+Mar!I52+Apr!I52+May!I52+June!I52+July!I52+Aug!I52+Sep!I52+Oct!I52+Nov!I52+Dec!I52 -> 406 | J52: =Jan!J52+Feb!J52+Mar!J52+Apr!J52+May!J52+June!J52+July!J52+Aug!J52+Sep!J52+Oct!J52+Nov!J52+Dec!J52 -> 28 | K52: =Jan!K52+Feb!K52+Mar!K52+Apr!K52+May!K52+June!K52+July!K52+Aug!K52+Sep!K52+Oct!K52+Nov!K52+Dec!K52 -> 56612 | L52: =Jan!L52+Feb!L52+Mar!L52+Apr!L52+May!L52+June!L52+July!L52+Aug!L52+Sep!L52+Oct!L52+Nov!L52+Dec!L52 -> 0 | M52: =Jan!M52+Feb!M52+Mar!M52+Apr!M52+May!M52+June!M52+July!M52+Aug!M52+Sep!M52+Oct!M52+Nov!M52+Dec!M52 -> 8 | N52: =Jan!N52+Feb!N52+Mar!N52+Apr!N52+May!N52+June!N52+July!N52+Aug!N52+Sep!N52+Oct!N52+Nov!N52+Dec!N52 -> 18077 | ... S52: =Jan!S52+Feb!S52+Mar!S52+Apr!S52+May!S52+June!S52+July!S52+Aug!S52+Sep!S52+Oct!S52+Nov!S52+Dec!S52 -> 0
E53: K4 | G53: =Jan!G53+Feb!G53+Mar!G53+Apr!G53+May!G53+June!G53+July!G53+Aug!G53+Sep!G53+Oct!G53+Nov!G53+Dec!G53 -> 183459 | H53: =Jan!H53+Feb!H53+Mar!H53+Apr!H53+May!H53+June!H53+July!H53+Aug!H53+Sep!H53+Oct!H53+Nov!H53+Dec!H53 -> 0 | I53: =Jan!I53+Feb!I53+Mar!I53+Apr!I53+May!I53+June!I53+July!I53+Aug!I53+Sep!I53+Oct!I53+Nov!I53+Dec!I53 -> 140108 | J53: =Jan!J53+Feb!J53+Mar!J53+Apr!J53+May!J53+June!J53+July!J53+Aug!J53+Sep!J53+Oct!J53+Nov!J53+Dec!J53 -> 13984 | K53: =Jan!K53+Feb!K53+Mar!K53+Apr!K53+May!K53+June!K53+July!K53+Aug!K53+Sep!K53+Oct!K53+Nov!K53+Dec!K53 -> 14763 | L53: =Jan!L53+Feb!L53+Mar!L53+Apr!L53+May!L53+June!L53+July!L53+Aug!L53+Sep!L53+Oct!L53+Nov!L53+Dec!L53 -> 468 | M53: =Jan!M53+Feb!M53+Mar!M53+Apr!M53+May!M53+June!M53+July!M53+Aug!M53+Sep!M53+Oct!M53+Nov!M53+Dec!M53 -> 7 | N53: =Jan!N53+Feb!N53+Mar!N53+Apr!N53+May!N53+June!N53+July!N53+Aug!N53+Sep!N53+Oct!N53+Nov!N53+Dec!N53 -> 975 | ... S53: =Jan!S53+Feb!S53+Mar!S53+Apr!S53+May!S53+June!S53+July!S53+Aug!S53+Sep!S53+Oct!S53+Nov!S53+Dec!S53 -> 0
B54: Mexico Plant | G54: =Jan!G54+Feb!G54+Mar!G54+Apr!G54+May!G54+June!G54+July!G54+Aug!G54+Sep!G54+Oct!G54+Nov!G54+Dec!G54 -> 264923 | H54: =Jan!H54+Feb!H54+Mar!H54+Apr!H54+May!H54+June!H54+July!H54+Aug!H54+Sep!H54+Oct!H54+Nov!H54+Dec!H54 -> 0 | I54: =Jan!I54+Feb!I54+Mar!I54+Apr!I54+May!I54+June!I54+July!I54+Aug!I54+Sep!I54+Oct!I54+Nov!I54+Dec!I54 -> 140514 | J54: =Jan!J54+Feb!J54+Mar!J54+Apr!J54+May!J54+June!J54+July!J54+Aug!J54+Sep!J54+Oct!J54+Nov!J54+Dec!J54 -> 14015 | K54: =Jan!K54+Feb!K54+Mar!K54+Apr!K54+May!K54+June!K54+July!K54+Aug!K54+Sep!K54+Oct!K54+Nov!K54+Dec!K54 -> 71375 | L54: =Jan!L54+Feb!L54+Mar!L54+Apr!L54+May!L54+June!L54+July!L54+Aug!L54+Sep!L54+Oct!L54+Nov!L54+Dec!L54 -> 468 | M54: =Jan!M54+Feb!M54+Mar!M54+Apr!M54+May!M54+June!M54+July!M54+Aug!M54+Sep!M54+Oct!M54+Nov!M54+Dec!M54 -> 15 | N54: =Jan!N54+Feb!N54+Mar!N54+Apr!N54+May!N54+June!N54+July!N54+Aug!N54+Sep!N54+Oct!N54+Nov!N54+Dec!N54 -> 19054 | ... S54: =Jan!S54+Feb!S54+Mar!S54+Apr!S54+May!S54+June!S54+July!S54+Aug!S54+Sep!S54+Oct!S54+Nov!S54+Dec!S54 -> 0
E55: Rio (Pride) | G55: =Jan!G55+Feb!G55+Mar!G55+Apr!G55+May!G55+June!G55+July!G55+Aug!G55+Sep!G55+Oct!G55+Nov!G55+Dec!G55 -> 1 | H55: =Jan!H55+Feb!H55+Mar!H55+Apr!H55+May!H55+June!H55+July!H55+Aug!H55+Sep!H55+Oct!H55+Nov!H55+Dec!H55 -> 0 | I55: =Jan!I55+Feb!I55+Mar!I55+Apr!I55+May!I55+June!I55+July!I55+Aug!I55+Sep!I55+Oct!I55+Nov!I55+Dec!I55 -> 0 | J55: =Jan!J55+Feb!J55+Mar!J55+Apr!J55+May!J55+June!J55+July!J55+Aug!J55+Sep!J55+Oct!J55+Nov!J55+Dec!J55 -> 0 | K55: =Jan!K55+Feb!K55+Mar!K55+Apr!K55+May!K55+June!K55+July!K55+Aug!K55+Sep!K55+Oct!K55+Nov!K55+Dec!K55 -> 0 | L55: =Jan!L55+Feb!L55+Mar!L55+Apr!L55+May!L55+June!L55+July!L55+Aug!L55+Sep!L55+Oct!L55+Nov!L55+Dec!L55 -> 0 | M55: =Jan!M55+Feb!M55+Mar!M55+Apr!M55+May!M55+June!M55+July!M55+Aug!M55+Sep!M55+Oct!M55+Nov!M55+Dec!M55 -> 1 | N55: =Jan!N55+Feb!N55+Mar!N55+Apr!N55+May!N55+June!N55+July!N55+Aug!N55+Sep!N55+Oct!N55+Nov!N55+Dec!N55 -> 0 | ... S55: =Jan!S55+Feb!S55+Mar!S55+Apr!S55+May!S55+June!S55+July!S55+Aug!S55+Sep!S55+Oct!S55+Nov!S55+Dec!S55 -> 0
B56: *Russia Plant (HMMR) | G56: =Jan!G56+Feb!G56+Mar!G56+Apr!G56+May!G56+June!G56+July!G56+Aug!G56+Sep!G56+Oct!G56+Nov!G56+Dec!G56 -> 1 | H56: =Jan!H56+Feb!H56+Mar!H56+Apr!H56+May!H56+June!H56+July!H56+Aug!H56+Sep!H56+Oct!H56+Nov!H56+Dec!H56 -> 0 | I56: =Jan!I56+Feb!I56+Mar!I56+Apr!I56+May!I56+June!I56+July!I56+Aug!I56+Sep!I56+Oct!I56+Nov!I56+Dec!I56 -> 0 | J56: =Jan!J56+Feb!J56+Mar!J56+Apr!J56+May!J56+June!J56+July!J56+Aug!J56+Sep!J56+Oct!J56+Nov!J56+Dec!J56 -> 0 | K56: =Jan!K56+Feb!K56+Mar!K56+Apr!K56+May!K56+June!K56+July!K56+Aug!K56+Sep!K56+Oct!K56+Nov!K56+Dec!K56 -> 0 | L56: =Jan!L56+Feb!L56+Mar!L56+Apr!L56+May!L56+June!L56+July!L56+Aug!L56+Sep!L56+Oct!L56+Nov!L56+Dec!L56 -> 0 | M56: =Jan!M56+Feb!M56+Mar!M56+Apr!M56+May!M56+June!M56+July!M56+Aug!M56+Sep!M56+Oct!M56+Nov!M56+Dec!M56 -> 1 | N56: =Jan!N56+Feb!N56+Mar!N56+Apr!N56+May!N56+June!N56+July!N56+Aug!N56+Sep!N56+Oct!N56+Nov!N56+Dec!N56 -> 0 | ... S56: =Jan!S56+Feb!S56+Mar!S56+Apr!S56+May!S56+June!S56+July!S56+Aug!S56+Sep!S56+Oct!S56+Nov!S56+Dec!S56 -> 0
E57: Pegas | G57: =Jan!G57+Feb!G57+Mar!G57+Apr!G57+May!G57+June!G57+July!G57+Aug!G57+Sep!G57+Oct!G57+Nov!G57+Dec!G57 -> 64439 | H57: =Jan!H57+Feb!H57+Mar!H57+Apr!H57+May!H57+June!H57+July!H57+Aug!H57+Sep!H57+Oct!H57+Nov!H57+Dec!H57 -> 0 | I57: =Jan!I57+Feb!I57+Mar!I57+Apr!I57+May!I57+June!I57+July!I57+Aug!I57+Sep!I57+Oct!I57+Nov!I57+Dec!I57 -> 0 | J57: =Jan!J57+Feb!J57+Mar!J57+Apr!J57+May!J57+June!J57+July!J57+Aug!J57+Sep!J57+Oct!J57+Nov!J57+Dec!J57 -> 0 | K57: =Jan!K57+Feb!K57+Mar!K57+Apr!K57+May!K57+June!K57+July!K57+Aug!K57+Sep!K57+Oct!K57+Nov!K57+Dec!K57 -> 0 | L57: =Jan!L57+Feb!L57+Mar!L57+Apr!L57+May!L57+June!L57+July!L57+Aug!L57+Sep!L57+Oct!L57+Nov!L57+Dec!L57 -> 0 | M57: =Jan!M57+Feb!M57+Mar!M57+Apr!M57+May!M57+June!M57+July!M57+Aug!M57+Sep!M57+Oct!M57+Nov!M57+Dec!M57 -> 104 | N57: =Jan!N57+Feb!N57+Mar!N57+Apr!N57+May!N57+June!N57+July!N57+Aug!N57+Sep!N57+Oct!N57+Nov!N57+Dec!N57 -> 26249 | ... S57: =Jan!S57+Feb!S57+Mar!S57+Apr!S57+May!S57+June!S57+July!S57+Aug!S57+Sep!S57+Oct!S57+Nov!S57+Dec!S57 -> 139
E58: Forte | G58: =Jan!G58+Feb!G58+Mar!G58+Apr!G58+May!G58+June!G58+July!G58+Aug!G58+Sep!G58+Oct!G58+Nov!G58+Dec!G58 -> 9386 | H58: =Jan!H58+Feb!H58+Mar!H58+Apr!H58+May!H58+June!H58+July!H58+Aug!H58+Sep!H58+Oct!H58+Nov!H58+Dec!H58 -> 0 | I58: =Jan!I58+Feb!I58+Mar!I58+Apr!I58+May!I58+June!I58+July!I58+Aug!I58+Sep!I58+Oct!I58+Nov!I58+Dec!I58 -> 0 | J58: =Jan!J58+Feb!J58+Mar!J58+Apr!J58+May!J58+June!J58+July!J58+Aug!J58+Sep!J58+Oct!J58+Nov!J58+Dec!J58 -> 0 | K58: =Jan!K58+Feb!K58+Mar!K58+Apr!K58+May!K58+June!K58+July!K58+Aug!K58+Sep!K58+Oct!K58+Nov!K58+Dec!K58 -> 0 | L58: =Jan!L58+Feb!L58+Mar!L58+Apr!L58+May!L58+June!L58+July!L58+Aug!L58+Sep!L58+Oct!L58+Nov!L58+Dec!L58 -> 0 | M58: =Jan!M58+Feb!M58+Mar!M58+Apr!M58+May!M58+June!M58+July!M58+Aug!M58+Sep!M58+Oct!M58+Nov!M58+Dec!M58 -> 0 | N58: =Jan!N58+Feb!N58+Mar!N58+Apr!N58+May!N58+June!N58+July!N58+Aug!N58+Sep!N58+Oct!N58+Nov!N58+Dec!N58 -> 0 | ... S58: =Jan!S58+Feb!S58+Mar!S58+Apr!S58+May!S58+June!S58+July!S58+Aug!S58+Sep!S58+Oct!S58+Nov!S58+Dec!S58 -> 9386
E59: K3 | G59: =Jan!G59+Feb!G59+Mar!G59+Apr!G59+May!G59+June!G59+July!G59+Aug!G59+Sep!G59+Oct!G59+Nov!G59+Dec!G59 -> 6525 | H59: =Jan!H59+Feb!H59+Mar!H59+Apr!H59+May!H59+June!H59+July!H59+Aug!H59+Sep!H59+Oct!H59+Nov!H59+Dec!H59 -> 0 | I59: =Jan!I59+Feb!I59+Mar!I59+Apr!I59+May!I59+June!I59+July!I59+Aug!I59+Sep!I59+Oct!I59+Nov!I59+Dec!I59 -> 0 | J59: =Jan!J59+Feb!J59+Mar!J59+Apr!J59+May!J59+June!J59+July!J59+Aug!J59+Sep!J59+Oct!J59+Nov!J59+Dec!J59 -> 0 | K59: =Jan!K59+Feb!K59+Mar!K59+Apr!K59+May!K59+June!K59+July!K59+Aug!K59+Sep!K59+Oct!K59+Nov!K59+Dec!K59 -> 0 | L59: =Jan!L59+Feb!L59+Mar!L59+Apr!L59+May!L59+June!L59+July!L59+Aug!L59+Sep!L59+Oct!L59+Nov!L59+Dec!L59 -> 0 | M59: =Jan!M59+Feb!M59+Mar!M59+Apr!M59+May!M59+June!M59+July!M59+Aug!M59+Sep!M59+Oct!M59+Nov!M59+Dec!M59 -> 0 | N59: =Jan!N59+Feb!N59+Mar!N59+Apr!N59+May!N59+June!N59+July!N59+Aug!N59+Sep!N59+Oct!N59+Nov!N59+Dec!N59 -> 0 | ... S59: =Jan!S59+Feb!S59+Mar!S59+Apr!S59+May!S59+June!S59+July!S59+Aug!S59+Sep!S59+Oct!S59+Nov!S59+Dec!S59 -> 6525
...

Sheet Jan
Q1: Jan. 2025, Kia IR
B2: ]
B3: Retail Sales by Country_2025 | S3: (Units, %)
B4: Model / Plant | G4: Total | H4: Korea | I4: U.S.A | J4: Canada | K4: Mexico | L4: *Europe | M4: Eastern Europe | N4: Latin America | O4: Middle East | P4: Africa | Q4: Asia Pacific | R4: India | S4: China
E6: Morning / Picanto | G6: 11876 | H6: 1484 | I6: 0 | L6: 6380 | M6: 82 | N6: 1440 | O6: 1290 | P6: 515 | Q6: 685 | R6: 0 | S6: 0
E7: Pride / Rio | G7: 1 | H7: 0 | I7: 0 | L7: 0 | M7: 0 | N7: 0 | O7: 0 | P7: 0 | Q7: 1 | R7: 0 | S7: 0
E8: Ray | G8: 3803 | H8: 3803 | I8: 0 | L8: 0 | M8: 0 | N8: 0 | Q8: 0 | R8: 0 | S8: 0
E9: Ray EV | G9: 73 | H9: 73 | I9: 0 | L9: 0 | M9: 0 | N9: 0 | Q9: 0 | R9: 0 | S9: 0
E10: K3 | G10: 687 | H10: 0 | I10: 0 | J10: 5 | K10: 2 | L10: 0 | M10: 15 | N10: 5 | O10: 181 | P10: 70 | Q10: 409 | R10: 0 | S10: 0
E11: K5 | G11: 7790 | H11: 2583 | I11: 4358 | J11: 0 | K11: 0 | L11: 0 | M11: 10 | N11: 15 | O11: 824 | P11: 0 | Q11: 0 | R11: 0 | S11: 0
E12: Stinger | G12: 0 | H12: 0 | I12: 0 | J12: 0 | K12: 0 | L12: 0 | M12: 0 | N12: 0 | O12: 0 | P12: 0 | Q12: 0 | R12: 0 | S12: 0
E13: K8 | G13: 2348 | H13: 2297 | I13: 0 | J13: 0 | K13: 0 | L13: 0 | M13: 15 | N13: 0 | O13: 36 | P13: 0 | Q13: 0 | R13: 0 | S13: 0
E14: K9 | G14: 125 | H14: 123 | I14: 0 | J14: 0 | K14: 0 | L14: 0 | M14: 2 | N14: 0 | O14: 0 | P14: 0 | Q14: 0 | R14: 0 | S14: 0
E15: Stonic | G15: 6006 | H15: 0 | I15: 0 | L15: 4531 | M15: 141 | N15: 117 | O15: 340 | P15: 129 | Q15: 748 | R15: 0 | S15: 0
E16: Seltos | G16: 10210 | H16: 4342 | I16: 2840 | J16: 1076 | K16: 0 | L16: 0 | M16: 110 | N16: 521 | O16: 496 | P16: 0 | Q16: 825 | R16: 0 | S16: 0
E17: Soul | G17: 4011 | H17: 0 | I17: 3554 | J17: 132 | K17: 6 | L17: 0 | M17: 8 | N17: 303 | O17: 0 | P17: 0 | Q17: 8 | R17: 0 | S17: 0
E18: Soul EV | G18: 5 | H18: 0 | I18: 0 | J18: 0 | K18: 0 | L18: 5 | M18: 0 | N18: 0 | O18: 0 | P18: 0 | Q18: 0 | R18: 0 | S18: 0
E19: Niro | G19: 6148 | H19: 560 | I19: 960 | J19: 217 | K19: 91 | L19: 3089 | M19: 12 | N19: 236 | O19: 790 | P19: 72 | Q19: 121 | R19: 0 | S19: 0
E20: Niro EV | G20: 1050 | H20: 11 | I20: 242 | J20: 82 | K20: 0 | L20: 691 | M20: 4 | N20: 1 | O20: 0 | P20: 3 | Q20: 16 | R20: 0 | S20: 0
E21: Niro Plus | G21: 1 | H21: 0 | I21: 0 | L21: 0 | M21: 0 | N21: 0 | O21: 0 | P21: 0 | Q21: 1 | R21: 0 | S21: 0
E22: Niro Plus EV | G22: 0 | H22: 0 | I22: 0 | L22: 0 | M22: 0 | N22: 0 | O22: 0 | P22: 0 | Q22: 0 | R22: 0 | S22: 0
E23: EV3 | G23: 5544 | H23: 429 | I23: 0 | L23: 5006 | M23: 109 | N23: 0 | O23: 0 | P23: 0 | Q23: 0 | R23: 0 | S23: 0
E24: EV4 | G24: 0 | H24: 0 | I24: 0 | J24: 0 | K24: 0 | L24: 0 | M24: 0 | N24: 0 | O24: 0 | P24: 0 | Q24: 0 | R24: 0 | S24: 0
E25: EV5 | G25: 0 | H25: 0 | I25: 0 | L25: 0 | N25: 0 | O25: 0 | P25: 0 | Q25: 0 | R25: 0 | S25: 0
E26: EV6 | G26: 3486 | H26: 72 | I26: 1542 | J26: 268 | K26: 12 | L26: 1464 | M26: 2 | N26: 4 | O26: 5 | P26: 2 | Q26: 77 | R26: 34 | S26: 4
E27: EV9 | G27: 1795 | H27: 37 | I27: 588 | J27: 308 | K27: 0 | L27: 778 | M27: 12 | N27: 10 | O27: 11 | P27: 4 | Q27: 47 | R27: 0 | S27: 0
E28: Sportage | G28: 15378 | H28: 6547 | I28: 3948 | J28: 1109 | K28: 499 | L28: 0 | M28: 310 | N28: 601 | O28: 0 | P28: 0 | Q28: 2364 | R28: 0 | S28: 0
E29: Sorento | G29: 13433 | H29: 7454 | I29: 1627 | J29: 211 | K29: 0 | L29: 1127 | M29: 232 | N29: 176 | O29: 1716 | P29: 62 | Q29: 828 | R29: 0 | S29: 0
E30: Mohave | G30: 43 | H30: 0 | I30: 0 | L30: 0 | M30: 43 | N30: 0 | Q30: 0 | R30: 0 | S30: 0
E31: Carnival | G31: 11481 | H31: 6068 | I31: 3665 | J31: 337 | K31: 0 | L31: 0 | M31: 12 | N31: 100 | O31: 405 | P31: 24 | Q31: 870 | R31: 0 | S31: 0
E32: Tasman | G32: 0 | H32: 0 | I32: 0 | L32: 0 | N32: 0 | O32: 0 | P32: 0 | Q32: 0 | R32: 0 | S32: 0
E33: Bongo | G33: 4831 | H33: 2419 | I33: 0 | L33: 0 | M33: 10 | N33: 851 | O33: 1297 | P33: 117 | Q33: 137 | R33: 0 | S33: 0
E34: Bongo EV | G34: 0 | H34: 0 | I34: 0 | L34: 0 | M34: 0 | N34: 0 | O34: 0 | P34: 0 | Q34: 0 | R34: 0 | S34: 0
E35: Bus | G35: 101 | H35: 101 | I35: 0 | L35: 0 | M35: 0 | N35: 0 | O35: 0 | P35: 0 | Q35: 0 | R35: 0 | S35: 0
E36: PV5 | G36: 0 | H36: 0 | I36: 0 | L36: 0 | N36: 0 | O36: 0 | P36: 0 | Q36: 0 | R36: 0 | S36: 0
B37: Korea Plants | G37: 110226 | H37: 38403 | I37: 23324 | J37: 3745 | K37: 610 | L37: 23071 | M37: 1129 | N37: 4380 | O37: 7391 | P37: 998 | Q37: 7137 | R37: 34 | S37: 4
E38: Optima / K5 | G38: -1 | H38: 0 | I38: -1 | J38: 0 | K38: 0 | L38: 0 | M38: 0 | N38: 0 | O38: 0 | P38: 0 | Q38: 0 | R38: 0 | S38: 0
E39: Sportage | G39: 7427 | H39: 0 | I39: 7409 | J39: 0 | K39: 0 | L39: 0 | M39: 0 | N39: 18 | Q39: 0 | R39: 0 | S39: 0
E40: Sorento | G40: 6330 | H40: 0 | I40: 5244 | J40: 806 | K40: 231 | L40: 0 | M40: 0 | N40: 49 | O40: 0 | P40: 0 | Q40: 0 | R40: 0 | S40: 0
E41: Telluride | G41: 9104 | H41: 0 | I41: 8771 | J41: 215 | K41: 57 | L41: 0 | N41: 8 | O41: 49 | P41: 0 | Q41: 4 | R41: 0 | S41: 0
...

Sheet Feb
Q1: Feb. 2025, Kia IR
B2: ]
B3: Retail Sales by Country_2025 | S3: (Units, %)
B4: Model / Plant | G4: Total | H4: Korea | I4: U.S.A | J4: Canada | K4: Mexico | L4: *Europe | M4: Eastern Europe | N4: Latin America | O4: Middle East | P4: Africa | Q4: Asia Pacific | R4: India | S4: China
E6: Morning / Picanto | G6: 8145 | H6: 765 | I6: 0 | L6: 3591 | M6: 62 | N6: 1379 | O6: 1265 | P6: 528 | Q6: 555 | R6: 0 | S6: 0
E7: Pride / Rio | G7: 0 | H7: 0 | I7: 0 | L7: 0 | M7: 0 | N7: 0 | O7: 0 | P7: 0 | Q7: 0 | R7: 0 | S7: 0
E8: Ray | G8: 3774 | H8: 3774 | I8: 0 | L8: 0 | M8: 0 | N8: 0 | Q8: 0 | R8: 0 | S8: 0
E9: Ray EV | G9: 513 | H9: 513 | I9: 0 | L9: 0 | M9: 0 | N9: 0 | Q9: 0 | R9: 0 | S9: 0
E10: K3 | G10: 509 | H10: 0 | I10: 0 | J10: 2 | K10: 1 | L10: 0 | M10: 24 | N10: 3 | O10: 113 | P10: 65 | Q10: 301 | R10: 0 | S10: 0
E11: K5 | G11: 7898 | H11: 2503 | I11: 4990 | J11: 0 | K11: 0 | L11: 0 | M11: 0 | N11: 11 | O11: 393 | P11: 0 | Q11: 1 | R11: 0 | S11: 0
E12: Stinger | G12: 0 | H12: 0 | I12: 0 | J12: 0 | K12: 0 | L12: 0 | M12: 0 | N12: 0 | O12: 0 | P12: 0 | Q12: 0 | R12: 0 | S12: 0
E13: K8 | G13: 2522 | H13: 2457 | I13: 0 | J13: 0 | K13: 0 | L13: 0 | M13: 26 | N13: 0 | O13: 39 | P13: 0 | Q13: 0 | R13: 0 | S13: 0
E14: K9 | G14: 169 | H14: 164 | I14: 0 | J14: 0 | K14: 0 | L14: 0 | M14: 5 | N14: 0 | O14: 0 | P14: 0 | Q14: 0 | R14: 0 | S14: 0
E15: Stonic | G15: 6351 | H15: 0 | I15: 0 | L15: 4646 | M15: 179 | N15: 175 | O15: 319 | P15: 298 | Q15: 734 | R15: 0 | S15: 0
E16: Seltos | G16: 11642 | H16: 4764 | I16: 3707 | J16: 1180 | K16: 0 | L16: 0 | M16: 35 | N16: 588 | O16: 180 | P16: 0 | Q16: 1188 | R16: 0 | S16: 0
E17: Soul | G17: 4572 | H17: 0 | I17: 4006 | J17: 250 | K17: 12 | L17: 0 | M17: 12 | N17: 287 | O17: 0 | P17: 0 | Q17: 5 | R17: 0 | S17: 0
E18: Soul EV | G18: 5 | H18: 0 | I18: 0 | J18: 0 | K18: 0 | L18: 4 | M18: 0 | N18: 1 | O18: 0 | P18: 0 | Q18: 0 | R18: 0 | S18: 0
E19: Niro | G19: 6889 | H19: 800 | I19: 1147 | J19: 272 | K19: 78 | L19: 2859 | M19: 2 | N19: 227 | O19: 1266 | P19: 85 | Q19: 153 | R19: 0 | S19: 0
E20: Niro EV | G20: 1152 | H20: 53 | I20: 338 | J20: 87 | K20: 0 | L20: 631 | M20: 5 | N20: 4 | O20: 0 | P20: 4 | Q20: 30 | R20: 0 | S20: 0
E21: Niro Plus | G21: 0 | H21: 0 | I21: 0 | L21: 0 | M21: 0 | N21: 0 | O21: 0 | P21: 0 | Q21: 0 | R21: 0 | S21: 0
E22: Niro Plus EV | G22: 1 | H22: 1 | I22: 0 | L22: 0 | M22: 0 | N22: 0 | O22: 0 | P22: 0 | Q22: 0 | R22: 0 | S22: 0
E23: EV3 | G23: 7865 | H23: 2257 | I23: 0 | L23: 5063 | M23: 540 | N23: 0 | O23: 0 | P23: 5 | Q23: 0 | R23: 0 | S23: 0
E24: EV4 | G24: 0 | H24: 0 | I24: 0 | J24: 0 | K24: 0 | L24: 0 | M24: 0 | N24: 0 | O24: 0 | P24: 0 | Q24: 0 | R24: 0 | S24: 0
E25: EV5 | G25: 0 | H25: 0 | I25: 0 | L25: 0 | M25: 0 | N25: 0 | O25: 0 | P25: 0 | Q25: 0 | R25: 0 | S25: 0
E26: EV6 | G26: 4023 | H26: 1100 | I26: 1275 | J26: 65 | K26: 5 | L26: 1324 | M26: 148 | N26: 5 | O26: 12 | P26: 8 | Q26: 67 | R26: 13 | S26: 1
E27: EV9 | G27: 1601 | H27: 88 | I27: 599 | J27: 160 | K27: 0 | L27: 650 | M27: 22 | N27: 8 | O27: 15 | P27: 5 | Q27: 54 | R27: 0 | S27: 0
E28: Sportage | G28: 16047 | H28: 6568 | I28: 4431 | J28: 1373 | K28: 536 | L28: 0 | M28: 314 | N28: 421 | O28: 6 | P28: 0 | Q28: 2398 | R28: 0 | S28: 0
E29: Sorento | G29: 15326 | H29: 9067 | I29: 1759 | J29: 204 | K29: 0 | L29: 961 | M29: 142 | N29: 162 | O29: 1781 | P29: 83 | Q29: 1167 | R29: 0 | S29: 0
E30: Mohave | G30: 2 | H30: 0 | I30: 0 | L30: 0 | M30: 2 | N30: 0 | Q30: 0 | R30: 0 | S30: 0
E31: Carnival | G31: 14825 | H31: 7734 | I31: 4440 | J31: 548 | K31: 0 | L31: 0 | M31: 18 | N31: 102 | O31: 354 | P31: 9 | Q31: 1620 | R31: 0 | S31: 0
E32: Tasman | G32: 0 | H32: 0 | I32: 0 | L32: 0 | M32: 0 | N32: 0 | O32: 0 | P32: 0 | Q32: 0 | R32: 0 | S32: 0
E33: Bongo | G33: 5423 | H33: 2627 | I33: 0 | L33: 0 | M33: 53 | N33: 907 | O33: 1373 | P33: 209 | Q33: 254 | R33: 0 | S33: 0
E34: Bongo EV | G34: 654 | H34: 654 | I34: 0 | L34: 0 | M34: 0 | N34: 0 | O34: 0 | P34: 0 | Q34: 0 | R34: 0 | S34: 0
E35: Bus | G35: 114 | H35: 114 | I35: 0 | L35: 0 | M35: 0 | N35: 0 | O35: 0 | P35: 0 | Q35: 0 | R35: 0 | S35: 0
E36: PV5 | G36: 0 | H36: 0 | I36: 0 | L36: 0 | M36: 0 | N36: 0 | O36: 0 | P36: 0 | Q36: 0 | R36: 0 | S36: 0
B37: Korea Plants | G37: 120022 | H37: 46003 | I37: 26692 | J37: 4141 | K37: 632 | L37: 19729 | M37: 1589 | N37: 4280 | O37: 7116 | P37: 1299 | Q37: 8527 | R37: 13 | S37: 1
E38: Optima / K5 | G38: 1 | H38: 0 | I38: 1 | J38: 0 | K38: 0 | L38: 0 | M38: 0 | N38: 0 | O38: 0 | P38: 0 | Q38: 0 | R38: 0 | S38: 0
E39: Sportage | G39: 8663 | H39: 0 | I39: 8641 | J39: 0 | K39: 0 | L39: 0 | M39: 0 | N39: 22 | Q39: 0 | R39: 0 | S39: 0
E40: Sorento | G40: 6886 | H40: 0 | I40: 5940 | J40: 741 | K40: 166 | L40: 0 | M40: 0 | N40: 39 | O40: 0 | P40: 0 | Q40: 0 | R40: 0 | S40: 0
E41: Telluride | G41: 9963 | H41: 0 | I41: 9599 | J41: 244 | K41: 43 | L41: 0 | M41: 0 | N41: 15 | O41: 61 | P41: 0 | Q41: 1 | R41: 0 | S41: 0
...

Sheet Mar
Q1: Mar. 2025, Kia IR
B2: ]
B3: Retail Sales by Country_2025 | S3: (Units, %)
B4: Model / Plant | G4: Total | H4: Korea | I4: U.S.A | J4: Canada | K4: Mexico | L4: *Europe | M4: Eastern Europe | N4: Latin America | O4: Middle East | P4: Africa | Q4: Asia Pacific | R4: India | S4: China
E6: Morning / Picanto | G6: 11145 | H6: 579 | I6: 0 | L6: 6327 | M6: 121 | N6: 1511 | O6: 1091 | P6: 634 | Q6: 882 | R6: 0 | S6: 0
E7: Pride / Rio | G7: 0 | H7: 0 | I7: 0 | L7: 0 | M7: 0 | N7: 0 | O7: 0 | P7: 0 | Q7: 0 | R7: 0 | S7: 0
E8: Ray | G8: 3375 | H8: 3375 | I8: 0 | L8: 0 | M8: 0 | N8: 0 | Q8: 0 | R8: 0 | S8: 0
E9: Ray EV | G9: 1209 | H9: 1209 | I9: 0 | L9: 0 | M9: 0 | N9: 0 | Q9: 0 | R9: 0 | S9: 0
E10: K3 | G10: 397 | H10: 0 | I10: 0 | J10: 2 | K10: 0 | L10: 0 | M10: 13 | N10: 6 | O10: 84 | P10: 65 | Q10: 227 | R10: 0 | S10: 0
E11: K5 | G11: 10130 | H11: 2863 | I11: 6399 | J11: 0 | K11: 0 | L11: 0 | M11: 1 | N11: 14 | O11: 853 | P11: 0 | Q11: 0 | R11: 0 | S11: 0
E12: Stinger | G12: 1 | H12: 0 | I12: 0 | J12: 0 | K12: 0 | L12: 0 | M12: 0 | N12: 0 | O12: 0 | P12: 1 | Q12: 0 | R12: 0 | S12: 0
E13: K8 | G13: 2807 | H13: 2704 | I13: 0 | J13: 0 | K13: 0 | L13: 0 | M13: 15 | N13: 0 | O13: 88 | P13: 0 | Q13: 0 | R13: 0 | S13: 0
E14: K9 | G14: 232 | H14: 226 | I14: 0 | J14: 0 | K14: 0 | L14: 0 | M14: 6 | N14: 0 | O14: 0 | P14: 0 | Q14: 0 | R14: 0 | S14: 0
E15: Stonic | G15: 8214 | H15: 0 | I15: 0 | L15: 5766 | M15: 301 | N15: 203 | O15: 524 | P15: 703 | Q15: 717 | R15: 0 | S15: 0
E16: Seltos | G16: 13651 | H16: 5351 | I16: 4828 | J16: 1420 | K16: 0 | L16: 0 | M16: 41 | N16: 730 | O16: 253 | P16: 0 | Q16: 1028 | R16: 0 | S16: 0
E17: Soul | G17: 4322 | H17: 0 | I17: 3717 | J17: 209 | K17: 7 | L17: 0 | M17: 33 | N17: 348 | O17: 0 | P17: 0 | Q17: 8 | R17: 0 | S17: 0
E18: Soul EV | G18: 5 | H18: 0 | I18: 0 | J18: 0 | K18: 0 | L18: 5 | M18: 0 | N18: 0 | O18: 0 | P18: 0 | Q18: 0 | R18: 0 | S18: 0
E19: Niro | G19: 9776 | H19: 1147 | I19: 1851 | J19: 558 | K19: 77 | L19: 5160 | M19: 6 | N19: 247 | O19: 480 | P19: 47 | Q19: 203 | R19: 0 | S19: 0
E20: Niro EV | G20: 2157 | H20: 29 | I20: 580 | J20: 150 | K20: 0 | L20: 1369 | M20: 2 | N20: 1 | O20: 3 | P20: 3 | Q20: 20 | R20: 0 | S20: 0
E21: Niro Plus | G21: 1 | H21: 0 | I21: 0 | L21: 0 | M21: 0 | N21: 0 | O21: 0 | P21: 1 | Q21: 0 | R21: 0 | S21: 0
E22: Niro Plus EV | G22: 0 | H22: 0 | I22: 0 | L22: 0 | M22: 0 | N22: 0 | O22: 0 | P22: 0 | Q22: 0 | R22: 0 | S22: 0
E23: EV3 | G23: 12212 | H23: 3032 | I23: 0 | L23: 7809 | M23: 1173 | N23: 4 | O23: 0 | P23: 8 | Q23: 186 | R23: 0 | S23: 0
E24: EV4 | G24: 0 | H24: 0 | I24: 0 | J24: 0 | K24: 0 | L24: 0 | M24: 0 | N24: 0 | O24: 0 | P24: 0 | Q24: 0 | R24: 0 | S24: 0
E25: EV5 | G25: 0 | H25: 0 | I25: 0 | L25: 0 | M25: 0 | N25: 0 | O25: 0 | P25: 0 | Q25: 0 | R25: 0 | S25: 0
E26: EV6 | G26: 4478 | H26: 1163 | I26: 921 | J26: 25 | K26: 9 | L26: 1965 | M26: 249 | N26: 4 | O26: 4 | P26: 4 | Q26: 115 | R26: 16 | S26: 3
E27: EV9 | G27: 1957 | H27: 202 | I27: 466 | J27: 203 | K27: 0 | L27: 997 | M27: 6 | N27: 11 | O27: 8 | P27: 2 | Q27: 60 | R27: 2 | S27: 0
E28: Sportage | G28: 18471 | H28: 6617 | I28: 5929 | J28: 2019 | K28: 470 | L28: 0 | M28: 418 | N28: 549 | O28: 1 | P28: 0 | Q28: 2468 | R28: 0 | S28: 0
E29: Sorento | G29: 17531 | H29: 10155 | I29: 2408 | J29: 263 | K29: 0 | L29: 1444 | M29: 153 | N29: 159 | O29: 1691 | P29: 68 | Q29: 1190 | R29: 0 | S29: 0
E30: Mohave | G30: 6 | H30: 0 | I30: 0 | L30: 0 | M30: 6 | N30: 0 | Q30: 0 | R30: 0 | S30: 0
E31: Carnival | G31: 16657 | H31: 7710 | I31: 6469 | J31: 454 | K31: 0 | L31: 0 | M31: 35 | N31: 134 | O31: 453 | P31: 10 | Q31: 1392 | R31: 0 | S31: 0
E32: Tasman | G32: 99 | H32: 96 | I32: 0 | L32: 0 | M32: 0 | N32: 3 | O32: 0 | P32: 0 | Q32: 0 | R32: 0 | S32: 0
E33: Bongo | G33: 5557 | H33: 2542 | I33: 0 | L33: 0 | M33: 26 | N33: 1038 | O33: 1475 | P33: 174 | Q33: 302 | R33: 0 | S33: 0
E34: Bongo EV | G34: 877 | H34: 877 | I34: 0 | L34: 0 | M34: 0 | N34: 0 | O34: 0 | P34: 0 | Q34: 0 | R34: 0 | S34: 0
E35: Bus | G35: 129 | H35: 129 | I35: 0 | L35: 0 | M35: 0 | N35: 0 | O35: 0 | P35: 0 | Q35: 0 | R35: 0 | S35: 0
E36: PV5 | G36: 0 | H36: 0 | I36: 0 | L36: 0 | M36: 0 | N36: 0 | O36: 0 | P36: 0 | Q36: 0 | R36: 0 | S36: 0
B37: Korea Plants | G37: 145396 | H37: 50006 | I37: 33568 | J37: 5303 | K37: 563 | L37: 30842 | M37: 2605 | N37: 4962 | O37: 7008 | P37: 1720 | Q37: 8798 | R37: 18 | S37: 3
E38: Optima / K5 | G38: 0 | H38: 0 | I38: 0 | J38: 0 | K38: 0 | L38: 0 | M38: 0 | N38: 0 | O38: 0 | P38: 0 | Q38: 0 | R38: 0 | S38: 0
E39: Sportage | G39: 10970 | H39: 0 | I39: 10943 | J39: 0 | K39: 0 | L39: 0 | M39: 0 | N39: 27 | Q39: 0 | R39: 0 | S39: 0
E40: Sorento | G40: 9762 | H40: 0 | I40: 8139 | J40: 1400 | K40: 152 | L40: 0 | M40: 0 | N40: 71 | O40: 0 | P40: 0 | Q40: 0 | R40: 0 | S40: 0
E41: Telluride | G41: 12009 | H41: 0 | I41: 11473 | J41: 386 | K41: 54 | L41: 0 | M41: 0 | N41: 19 | O41: 75 | P41: 0 | Q41: 2 | R41: 0 | S41: 0
...

Sheet Apr
Q1: Apr. 2025, Kia IR
B2: ]
B3: Retail Sales by Country_2025 | S3: (Units, %)
B4: Model / Plant | G4: Total | H4: Korea | I4: U.S.A | J4: Canada | K4: Mexico | L4: *Europe | M4: Eastern Europe | N4: Latin America | O4: Middle East | P4: Africa | Q4: Asia Pacific | R4: India | S4: China
E6: Morning / Picanto | G6: 10553 | H6: 1028 | I6: 0 | L6: 5621 | M6: 156 | N6: 1444 | O6: 138 | P6: 1409 | Q6: 757 | R6: 0 | S6: 0
E7: Pride / Rio | G7: 0 | H7: 0 | I7: 0 | L7: 0 | M7: 0 | N7: 0 | O7: 0 | P7: 0 | Q7: 0 | R7: 0 | S7: 0
E8: Ray | G8: 3634 | H8: 3634 | I8: 0 | L8: 0 | M8: 0 | N8: 0 | Q8: 0 | R8: 0 | S8: 0
E9: Ray EV | G9: 628 | H9: 628 | I9: 0 | L9: 0 | M9: 0 | N9: 0 | Q9: 0 | R9: 0 | S9: 0
E10: K3 | G10: 215 | H10: 0 | I10: 0 | J10: 3 | K10: 0 | L10: 0 | M10: 28 | N10: 4 | O10: 94 | P10: 0 | Q10: 86 | R10: 0 | S10: 0
E11: K5 | G11: 10972 | H11: 3581 | I11: 6245 | J11: 0 | K11: 0 | L11: 0 | M11: 3 | N11: 17 | O11: 1126 | P11: 0 | Q11: 0 | R11: 0 | S11: 0
E12: Stinger | G12: 2 | H12: 0 | I12: 0 | J12: 0 | K12: 0 | L12: 1 | M12: 0 | N12: 0 | O12: 0 | P12: 1 | Q12: 0 | R12: 0 | S12: 0
E13: K8 | G13: 2646 | H13: 2566 | I13: 0 | J13: 0 | K13: 0 | L13: 0 | M13: 10 | N13: 0 | O13: 70 | P13: 0 | Q13: 0 | R13: 0 | S13: 0
E14: K9 | G14: 153 | H14: 147 | I14: 0 | J14: 0 | K14: 0 | L14: 0 | M14: 6 | N14: 0 | O14: 0 | P14: 0 | Q14: 0 | R14: 0 | S14: 0
E15: Stonic | G15: 6758 | H15: 0 | I15: 0 | L15: 4475 | M15: 440 | N15: 193 | O15: 389 | P15: 656 | Q15: 605 | R15: 0 | S15: 0
E16: Seltos | G16: 12633 | H16: 5101 | I16: 4051 | J16: 1219 | K16: 0 | L16: 0 | M16: 123 | N16: 870 | O16: 328 | P16: 0 | Q16: 941 | R16: 0 | S16: 0
E17: Soul | G17: 5447 | H17: 0 | I17: 5069 | J17: 91 | K17: 3 | L17: 0 | M17: 36 | N17: 245 | O17: 0 | P17: 0 | Q17: 3 | R17: 0 | S17: 0
E18: Soul EV | G18: 2 | H18: 0 | I18: 0 | J18: 0 | K18: 0 | L18: 1 | M18: 0 | N18: 1 | O18: 0 | P18: 0 | Q18: 0 | R18: 0 | S18: 0
E19: Niro | G19: 8678 | H19: 1644 | I19: 1781 | J19: 727 | K19: 80 | L19: 3444 | M19: 2 | N19: 187 | O19: 634 | P19: 58 | Q19: 121 | R19: 0 | S19: 0
E20: Niro EV | G20: 1726 | H20: 72 | I20: 569 | J20: 330 | K20: 0 | L20: 745 | M20: 0 | N20: 0 | O20: 0 | P20: 5 | Q20: 5 | R20: 0 | S20: 0
E21: Niro Plus | G21: 4 | H21: 0 | I21: 0 | L21: 0 | M21: 0 | N21: 0 | O21: 0 | P21: 1 | Q21: 3 | R21: 0 | S21: 0
E22: Niro Plus EV | G22: 0 | H22: 0 | I22: 0 | L22: 0 | M22: 0 | N22: 0 | O22: 0 | P22: 0 | Q22: 0 | R22: 0 | S22: 0
E23: EV3 | G23: 10012 | H23: 3057 | I23: 0 | L23: 5551 | M23: 957 | N23: 54 | O23: 0 | P23: 6 | Q23: 387 | R23: 0 | S23: 0
E24: EV4 | G24: 831 | H24: 831 | I24: 0 | J24: 0 | K24: 0 | L24: 0 | M24: 0 | N24: 0 | O24: 0 | P24: 0 | Q24: 0 | R24: 0 | S24: 0
E25: EV5 | G25: 0 | H25: 0 | I25: 0 | L25: 0 | M25: 0 | N25: 0 | O25: 0 | P25: 0 | Q25: 0 | R25: 0 | S25: 0
E26: EV6 | G26: 3070 | H26: 789 | I26: 340 | J26: 24 | K26: 3 | L26: 1441 | M26: 350 | N26: 4 | O26: 9 | P26: 12 | Q26: 61 | R26: 37 | S26: 0
E27: EV9 | G27: 1890 | H27: 150 | I27: 115 | J27: 475 | K27: 0 | L27: 1070 | M27: 16 | N27: 3 | O27: 6 | P27: 0 | Q27: 52 | R27: 3 | S27: 0
E28: Sportage | G28: 18442 | H28: 6703 | I28: 5548 | J28: 2496 | K28: 529 | L28: 0 | M28: 439 | N28: 598 | O28: 4 | P28: 0 | Q28: 2125 | R28: 0 | S28: 0
E29: Sorento | G29: 15213 | H29: 8796 | I29: 2046 | J29: 326 | K29: 0 | L29: 898 | M29: 225 | N29: 167 | O29: 1640 | P29: 57 | Q29: 1058 | R29: 0 | S29: 0
E30: Mohave | G30: 0 | H30: 0 | I30: 0 | L30: 0 | M30: 0 | N30: 0 | Q30: 0 | R30: 0 | S30: 0
E31: Carnival | G31: 16558 | H31: 7592 | I31: 6405 | J31: 629 | K31: 0 | L31: 0 | M31: 18 | N31: 183 | O31: 640 | P31: 19 | Q31: 1072 | R31: 0 | S31: 0
E32: Tasman | G32: 1253 | H32: 1248 | I32: 0 | L32: 0 | M32: 0 | N32: 5 | O32: 0 | P32: 0 | Q32: 0 | R32: 0 | S32: 0
E33: Bongo | G33: 5622 | H33: 2806 | I33: 0 | L33: 0 | M33: 25 | N33: 1100 | O33: 1238 | P33: 166 | Q33: 287 | R33: 0 | S33: 0
E34: Bongo EV | G34: 498 | H34: 497 | I34: 0 | L34: 0 | M34: 1 | N34: 0 | O34: 0 | P34: 0 | Q34: 0 | R34: 0 | S34: 0
E35: Bus | G35: 135 | H35: 135 | I35: 0 | L35: 0 | M35: 0 | N35: 0 | O35: 0 | P35: 0 | Q35: 0 | R35: 0 | S35: 0
E36: PV5 | G36: 0 | H36: 0 | I36: 0 | L36: 0 | M36: 0 | N36: 0 | O36: 0 | P36: 0 | Q36: 0 | R36: 0 | S36: 0
B37: Korea Plants | G37: 137575 | H37: 51005 | I37: 32169 | J37: 6320 | K37: 615 | L37: 23247 | M37: 2835 | N37: 5075 | O37: 6316 | P37: 2390 | Q37: 7563 | R37: 40 | S37: 0
E38: Optima / K5 | G38: 3 | H38: 0 | I38: 3 | J38: 0 | K38: 0 | L38: 0 | M38: 0 | N38: 0 | O38: 0 | P38: 0 | Q38: 0 | R38: 0 | S38: 0
E39: Sportage | G39: 10651 | H39: 0 | I39: 10630 | J39: 0 | K39: 0 | L39: 0 | M39: 0 | N39: 21 | Q39: 0 | R39: 0 | S39: 0
E40: Sorento | G40: 9363 | H40: 0 | I40: 7613 | J40: 1542 | K40: 141 | L40: 0 | M40: 0 | N40: 66 | O40: 0 | P40: 0 | Q40: 1 | R40: 0 | S40: 0
E41: Telluride | G41: 11431 | H41: 0 | I41: 10860 | J41: 431 | K41: 28 | L41: 0 | M41: 0 | N41: 8 | O41: 103 | P41: 0 | Q41: 1 | R41: 0 | S41: 0
...

Sheet May
Q1: May. 2025, Kia IR
B2: ]
B3: Retail Sales by Country_2025 | S3: (Units, %)
B4: Model / Plant | G4: Total | H4: Korea | I4: U.S.A | J4: Canada | K4: Mexico | L4: *Europe | M4: Eastern Europe | N4: Latin America | O4: Middle East | P4: Africa | Q4: Asia Pacific | R4: India | S4: China
E6: Morning / Picanto | G6: 11697 | H6: 1527 | I6: 0 | L6: 5767 | M6: 68 | N6: 1277 | O6: 1502 | P6: 754 | Q6: 802 | R6: 0 | S6: 0
E7: Pride / Rio | G7: -5 | H7: 0 | I7: 0 | L7: 0 | M7: 0 | N7: 0 | O7: 0 | P7: 0 | Q7: -5 | R7: 0 | S7: 0
E8: Ray | G8: 3194 | H8: 3194 | I8: 0 | L8: 0 | M8: 0 | N8: 0 | Q8: 0 | R8: 0 | S8: 0
E9: Ray EV | G9: 806 | H9: 806 | I9: 0 | L9: 0 | M9: 0 | N9: 0 | Q9: 0 | R9: 0 | S9: 0
E10: K3 | G10: 143 | H10: 0 | I10: 0 | J10: 3 | K10: 0 | L10: 0 | M10: 11 | N10: 0 | O10: 59 | P10: 0 | Q10: 70 | R10: 0 | S10: 0
E11: K5 | G11: 10580 | H11: 3028 | I11: 6957 | J11: 0 | K11: 0 | L11: 0 | M11: 7 | N11: 15 | O11: 555 | P11: 0 | Q11: 18 | R11: 0 | S11: 0
E12: Stinger | G12: 0 | H12: 0 | I12: 0 | J12: 0 | K12: 0 | L12: 0 | M12: 0 | N12: 0 | O12: 0 | P12: 0 | Q12: 0 | R12: 0 | S12: 0
E13: K8 | G13: 2708 | H13: 2627 | I13: 0 | J13: 0 | K13: 0 | L13: 0 | M13: 16 | N13: 0 | O13: 65 | P13: 0 | Q13: 0 | R13: 0 | S13: 0
E14: K9 | G14: 112 | H14: 109 | I14: 0 | J14: 0 | K14: 0 | L14: 0 | M14: 3 | N14: 0 | O14: 0 | P14: 0 | Q14: 0 | R14: 0 | S14: 0
E15: Stonic | G15: 6449 | H15: 0 | I15: 0 | L15: 5031 | M15: 312 | N15: 220 | O15: 63 | P15: 180 | Q15: 643 | R15: 0 | S15: 0
E16: Seltos | G16: 13263 | H16: 4257 | I16: 5254 | J16: 1688 | K16: 0 | L16: 0 | M16: 171 | N16: 711 | O16: 93 | P16: 0 | Q16: 1089 | R16: 0 | S16: 0
E17: Soul | G17: 5438 | H17: 0 | I17: 5043 | J17: 11 | K17: 0 | L17: 0 | M17: 18 | N17: 361 | O17: 0 | P17: 0 | Q17: 5 | R17: 0 | S17: 0
E18: Soul EV | G18: 8 | H18: 0 | I18: 0 | J18: 0 | K18: 0 | L18: 8 | M18: 0 | N18: 0 | O18: 0 | P18: 0 | Q18: 0 | R18: 0 | S18: 0
E19: Niro | G19: 7526 | H19: 1283 | I19: 1703 | J19: 625 | K19: 88 | L19: 3183 | M19: 4 | N19: 192 | O19: 300 | P19: 46 | Q19: 102 | R19: 0 | S19: 0
E20: Niro EV | G20: 1836 | H20: 27 | I20: 651 | J20: 363 | K20: 0 | L20: 778 | M20: 2 | N20: 2 | O20: 1 | P20: 1 | Q20: 11 | R20: 0 | S20: 0
E21: Niro Plus | G21: 0 | H21: 0 | I21: 0 | L21: 0 | M21: 0 | N21: 0 | O21: 0 | P21: 0 | Q21: 0 | R21: 0 | S21: 0
E22: Niro Plus EV | G22: 0 | H22: 0 | I22: 0 | L22: 0 | M22: 0 | N22: 0 | O22: 0 | P22: 0 | Q22: 0 | R22: 0 | S22: 0
E23: EV3 | G23: 8200 | H23: 1866 | I23: 0 | L23: 5310 | M23: 620 | N23: 56 | O23: 0 | P23: 8 | Q23: 340 | R23: 0 | S23: 0
E24: EV4 | G24: 1375 | H24: 1373 | I24: 0 | J24: 0 | K24: 0 | L24: 2 | M24: 0 | N24: 0 | O24: 0 | P24: 0 | Q24: 0 | R24: 0 | S24: 0
E25: EV5 | G25: 0 | H25: 0 | I25: 0 | L25: 0 | M25: 0 | N25: 0 | O25: 0 | P25: 0 | Q25: 0 | R25: 0 | S25: 0
E26: EV6 | G26: 2869 | H26: 957 | I26: 92 | J26: 0 | K26: 2 | L26: 1389 | M26: 303 | N26: 4 | O26: 16 | P26: 9 | Q26: 48 | R26: 48 | S26: 1
E27: EV9 | G27: 1494 | H27: 178 | I27: 18 | J27: 400 | K27: 0 | L27: 819 | M27: 20 | N27: 3 | O27: 7 | P27: 4 | Q27: 44 | R27: 1 | S27: 0
E28: Sportage | G28: 16908 | H28: 5295 | I28: 5629 | J28: 2651 | K28: 509 | L28: 0 | M28: 483 | N28: 551 | O28: 4 | P28: 0 | Q28: 1786 | R28: 0 | S28: 0
E29: Sorento | G29: 14222 | H29: 7734 | I29: 1780 | J29: 415 | K29: 0 | L29: 1106 | M29: 204 | N29: 199 | O29: 1552 | P29: 65 | Q29: 1167 | R29: 0 | S29: 0
E30: Mohave | G30: 0 | H30: 0 | I30: 0 | L30: 0 | M30: 0 | N30: 0 | Q30: 0 | R30: 0 | S30: 0
